{
  "nbformat": 4,
  "nbformat_minor": 0,
  "metadata": {
    "colab": {
      "provenance": [],
      "authorship_tag": "ABX9TyNtLT51nwwQdgjmyJaXLo0w",
      "include_colab_link": true
    },
    "kernelspec": {
      "name": "python3",
      "display_name": "Python 3"
    },
    "language_info": {
      "name": "python"
    }
  },
  "cells": [
    {
      "cell_type": "markdown",
      "metadata": {
        "id": "view-in-github",
        "colab_type": "text"
      },
      "source": [
        "<a href=\"https://colab.research.google.com/github/brunomsm0/Bank/blob/master/ModelingEstudo.ipynb\" target=\"_parent\"><img src=\"https://colab.research.google.com/assets/colab-badge.svg\" alt=\"Open In Colab\"/></a>"
      ]
    },
    {
      "cell_type": "code",
      "execution_count": 40,
      "metadata": {
        "id": "nc9GU6fplLv2"
      },
      "outputs": [],
      "source": [
        "from sklearn import datasets\n",
        "from sklearn.model_selection import train_test_split, GridSearchCV\n",
        "from sklearn.linear_model import LinearRegression\n",
        "from sklearn.metrics import mean_squared_error\n",
        "from sklearn.svm import SVR\n",
        "from sklearn.tree import DecisionTreeRegressor\n",
        "import xgboost as xgb\n",
        "import numpy as np\n"
      ]
    },
    {
      "cell_type": "code",
      "source": [
        "housing = datasets.fetch_california_housing()"
      ],
      "metadata": {
        "id": "ye--sfzdoh5m"
      },
      "execution_count": 7,
      "outputs": []
    },
    {
      "cell_type": "code",
      "source": [
        "print(housing)"
      ],
      "metadata": {
        "colab": {
          "base_uri": "https://localhost:8080/"
        },
        "id": "tob5JRHLqQYj",
        "outputId": "840c158e-a537-43c9-d90f-1592b0eee7c5"
      },
      "execution_count": 9,
      "outputs": [
        {
          "output_type": "stream",
          "name": "stdout",
          "text": [
            "{'data': array([[   8.3252    ,   41.        ,    6.98412698, ...,    2.55555556,\n",
            "          37.88      , -122.23      ],\n",
            "       [   8.3014    ,   21.        ,    6.23813708, ...,    2.10984183,\n",
            "          37.86      , -122.22      ],\n",
            "       [   7.2574    ,   52.        ,    8.28813559, ...,    2.80225989,\n",
            "          37.85      , -122.24      ],\n",
            "       ...,\n",
            "       [   1.7       ,   17.        ,    5.20554273, ...,    2.3256351 ,\n",
            "          39.43      , -121.22      ],\n",
            "       [   1.8672    ,   18.        ,    5.32951289, ...,    2.12320917,\n",
            "          39.43      , -121.32      ],\n",
            "       [   2.3886    ,   16.        ,    5.25471698, ...,    2.61698113,\n",
            "          39.37      , -121.24      ]]), 'target': array([4.526, 3.585, 3.521, ..., 0.923, 0.847, 0.894]), 'frame': None, 'target_names': ['MedHouseVal'], 'feature_names': ['MedInc', 'HouseAge', 'AveRooms', 'AveBedrms', 'Population', 'AveOccup', 'Latitude', 'Longitude'], 'DESCR': '.. _california_housing_dataset:\\n\\nCalifornia Housing dataset\\n--------------------------\\n\\n**Data Set Characteristics:**\\n\\n    :Number of Instances: 20640\\n\\n    :Number of Attributes: 8 numeric, predictive attributes and the target\\n\\n    :Attribute Information:\\n        - MedInc        median income in block group\\n        - HouseAge      median house age in block group\\n        - AveRooms      average number of rooms per household\\n        - AveBedrms     average number of bedrooms per household\\n        - Population    block group population\\n        - AveOccup      average number of household members\\n        - Latitude      block group latitude\\n        - Longitude     block group longitude\\n\\n    :Missing Attribute Values: None\\n\\nThis dataset was obtained from the StatLib repository.\\nhttps://www.dcc.fc.up.pt/~ltorgo/Regression/cal_housing.html\\n\\nThe target variable is the median house value for California districts,\\nexpressed in hundreds of thousands of dollars ($100,000).\\n\\nThis dataset was derived from the 1990 U.S. census, using one row per census\\nblock group. A block group is the smallest geographical unit for which the U.S.\\nCensus Bureau publishes sample data (a block group typically has a population\\nof 600 to 3,000 people).\\n\\nA household is a group of people residing within a home. Since the average\\nnumber of rooms and bedrooms in this dataset are provided per household, these\\ncolumns may take surprisingly large values for block groups with few households\\nand many empty houses, such as vacation resorts.\\n\\nIt can be downloaded/loaded using the\\n:func:`sklearn.datasets.fetch_california_housing` function.\\n\\n.. topic:: References\\n\\n    - Pace, R. Kelley and Ronald Barry, Sparse Spatial Autoregressions,\\n      Statistics and Probability Letters, 33 (1997) 291-297\\n'}\n"
          ]
        }
      ]
    },
    {
      "cell_type": "code",
      "source": [
        "import pandas as pd"
      ],
      "metadata": {
        "id": "bE1etDkNrYMH"
      },
      "execution_count": 8,
      "outputs": []
    },
    {
      "cell_type": "code",
      "source": [
        "df = pd.DataFrame(housing.data, columns=housing.feature_names)"
      ],
      "metadata": {
        "id": "ZCSJQ3ZEqzT2"
      },
      "execution_count": 9,
      "outputs": []
    },
    {
      "cell_type": "code",
      "source": [
        "df.head()"
      ],
      "metadata": {
        "colab": {
          "base_uri": "https://localhost:8080/",
          "height": 206
        },
        "id": "tVnUC170rgLU",
        "outputId": "d8057d3a-075f-4ea8-df73-6d4214730842"
      },
      "execution_count": 13,
      "outputs": [
        {
          "output_type": "execute_result",
          "data": {
            "text/plain": [
              "   MedInc  HouseAge  AveRooms  AveBedrms  Population  AveOccup  Latitude  \\\n",
              "0  8.3252      41.0  6.984127   1.023810       322.0  2.555556     37.88   \n",
              "1  8.3014      21.0  6.238137   0.971880      2401.0  2.109842     37.86   \n",
              "2  7.2574      52.0  8.288136   1.073446       496.0  2.802260     37.85   \n",
              "3  5.6431      52.0  5.817352   1.073059       558.0  2.547945     37.85   \n",
              "4  3.8462      52.0  6.281853   1.081081       565.0  2.181467     37.85   \n",
              "\n",
              "   Longitude  \n",
              "0    -122.23  \n",
              "1    -122.22  \n",
              "2    -122.24  \n",
              "3    -122.25  \n",
              "4    -122.25  "
            ],
            "text/html": [
              "\n",
              "  <div id=\"df-c6012c38-1f86-4b94-be4f-d398b00e31a9\" class=\"colab-df-container\">\n",
              "    <div>\n",
              "<style scoped>\n",
              "    .dataframe tbody tr th:only-of-type {\n",
              "        vertical-align: middle;\n",
              "    }\n",
              "\n",
              "    .dataframe tbody tr th {\n",
              "        vertical-align: top;\n",
              "    }\n",
              "\n",
              "    .dataframe thead th {\n",
              "        text-align: right;\n",
              "    }\n",
              "</style>\n",
              "<table border=\"1\" class=\"dataframe\">\n",
              "  <thead>\n",
              "    <tr style=\"text-align: right;\">\n",
              "      <th></th>\n",
              "      <th>MedInc</th>\n",
              "      <th>HouseAge</th>\n",
              "      <th>AveRooms</th>\n",
              "      <th>AveBedrms</th>\n",
              "      <th>Population</th>\n",
              "      <th>AveOccup</th>\n",
              "      <th>Latitude</th>\n",
              "      <th>Longitude</th>\n",
              "    </tr>\n",
              "  </thead>\n",
              "  <tbody>\n",
              "    <tr>\n",
              "      <th>0</th>\n",
              "      <td>8.3252</td>\n",
              "      <td>41.0</td>\n",
              "      <td>6.984127</td>\n",
              "      <td>1.023810</td>\n",
              "      <td>322.0</td>\n",
              "      <td>2.555556</td>\n",
              "      <td>37.88</td>\n",
              "      <td>-122.23</td>\n",
              "    </tr>\n",
              "    <tr>\n",
              "      <th>1</th>\n",
              "      <td>8.3014</td>\n",
              "      <td>21.0</td>\n",
              "      <td>6.238137</td>\n",
              "      <td>0.971880</td>\n",
              "      <td>2401.0</td>\n",
              "      <td>2.109842</td>\n",
              "      <td>37.86</td>\n",
              "      <td>-122.22</td>\n",
              "    </tr>\n",
              "    <tr>\n",
              "      <th>2</th>\n",
              "      <td>7.2574</td>\n",
              "      <td>52.0</td>\n",
              "      <td>8.288136</td>\n",
              "      <td>1.073446</td>\n",
              "      <td>496.0</td>\n",
              "      <td>2.802260</td>\n",
              "      <td>37.85</td>\n",
              "      <td>-122.24</td>\n",
              "    </tr>\n",
              "    <tr>\n",
              "      <th>3</th>\n",
              "      <td>5.6431</td>\n",
              "      <td>52.0</td>\n",
              "      <td>5.817352</td>\n",
              "      <td>1.073059</td>\n",
              "      <td>558.0</td>\n",
              "      <td>2.547945</td>\n",
              "      <td>37.85</td>\n",
              "      <td>-122.25</td>\n",
              "    </tr>\n",
              "    <tr>\n",
              "      <th>4</th>\n",
              "      <td>3.8462</td>\n",
              "      <td>52.0</td>\n",
              "      <td>6.281853</td>\n",
              "      <td>1.081081</td>\n",
              "      <td>565.0</td>\n",
              "      <td>2.181467</td>\n",
              "      <td>37.85</td>\n",
              "      <td>-122.25</td>\n",
              "    </tr>\n",
              "  </tbody>\n",
              "</table>\n",
              "</div>\n",
              "    <div class=\"colab-df-buttons\">\n",
              "\n",
              "  <div class=\"colab-df-container\">\n",
              "    <button class=\"colab-df-convert\" onclick=\"convertToInteractive('df-c6012c38-1f86-4b94-be4f-d398b00e31a9')\"\n",
              "            title=\"Convert this dataframe to an interactive table.\"\n",
              "            style=\"display:none;\">\n",
              "\n",
              "  <svg xmlns=\"http://www.w3.org/2000/svg\" height=\"24px\" viewBox=\"0 -960 960 960\">\n",
              "    <path d=\"M120-120v-720h720v720H120Zm60-500h600v-160H180v160Zm220 220h160v-160H400v160Zm0 220h160v-160H400v160ZM180-400h160v-160H180v160Zm440 0h160v-160H620v160ZM180-180h160v-160H180v160Zm440 0h160v-160H620v160Z\"/>\n",
              "  </svg>\n",
              "    </button>\n",
              "\n",
              "  <style>\n",
              "    .colab-df-container {\n",
              "      display:flex;\n",
              "      gap: 12px;\n",
              "    }\n",
              "\n",
              "    .colab-df-convert {\n",
              "      background-color: #E8F0FE;\n",
              "      border: none;\n",
              "      border-radius: 50%;\n",
              "      cursor: pointer;\n",
              "      display: none;\n",
              "      fill: #1967D2;\n",
              "      height: 32px;\n",
              "      padding: 0 0 0 0;\n",
              "      width: 32px;\n",
              "    }\n",
              "\n",
              "    .colab-df-convert:hover {\n",
              "      background-color: #E2EBFA;\n",
              "      box-shadow: 0px 1px 2px rgba(60, 64, 67, 0.3), 0px 1px 3px 1px rgba(60, 64, 67, 0.15);\n",
              "      fill: #174EA6;\n",
              "    }\n",
              "\n",
              "    .colab-df-buttons div {\n",
              "      margin-bottom: 4px;\n",
              "    }\n",
              "\n",
              "    [theme=dark] .colab-df-convert {\n",
              "      background-color: #3B4455;\n",
              "      fill: #D2E3FC;\n",
              "    }\n",
              "\n",
              "    [theme=dark] .colab-df-convert:hover {\n",
              "      background-color: #434B5C;\n",
              "      box-shadow: 0px 1px 3px 1px rgba(0, 0, 0, 0.15);\n",
              "      filter: drop-shadow(0px 1px 2px rgba(0, 0, 0, 0.3));\n",
              "      fill: #FFFFFF;\n",
              "    }\n",
              "  </style>\n",
              "\n",
              "    <script>\n",
              "      const buttonEl =\n",
              "        document.querySelector('#df-c6012c38-1f86-4b94-be4f-d398b00e31a9 button.colab-df-convert');\n",
              "      buttonEl.style.display =\n",
              "        google.colab.kernel.accessAllowed ? 'block' : 'none';\n",
              "\n",
              "      async function convertToInteractive(key) {\n",
              "        const element = document.querySelector('#df-c6012c38-1f86-4b94-be4f-d398b00e31a9');\n",
              "        const dataTable =\n",
              "          await google.colab.kernel.invokeFunction('convertToInteractive',\n",
              "                                                    [key], {});\n",
              "        if (!dataTable) return;\n",
              "\n",
              "        const docLinkHtml = 'Like what you see? Visit the ' +\n",
              "          '<a target=\"_blank\" href=https://colab.research.google.com/notebooks/data_table.ipynb>data table notebook</a>'\n",
              "          + ' to learn more about interactive tables.';\n",
              "        element.innerHTML = '';\n",
              "        dataTable['output_type'] = 'display_data';\n",
              "        await google.colab.output.renderOutput(dataTable, element);\n",
              "        const docLink = document.createElement('div');\n",
              "        docLink.innerHTML = docLinkHtml;\n",
              "        element.appendChild(docLink);\n",
              "      }\n",
              "    </script>\n",
              "  </div>\n",
              "\n",
              "\n",
              "<div id=\"df-705eb8fb-da1a-4b9d-a613-9609e1743180\">\n",
              "  <button class=\"colab-df-quickchart\" onclick=\"quickchart('df-705eb8fb-da1a-4b9d-a613-9609e1743180')\"\n",
              "            title=\"Suggest charts\"\n",
              "            style=\"display:none;\">\n",
              "\n",
              "<svg xmlns=\"http://www.w3.org/2000/svg\" height=\"24px\"viewBox=\"0 0 24 24\"\n",
              "     width=\"24px\">\n",
              "    <g>\n",
              "        <path d=\"M19 3H5c-1.1 0-2 .9-2 2v14c0 1.1.9 2 2 2h14c1.1 0 2-.9 2-2V5c0-1.1-.9-2-2-2zM9 17H7v-7h2v7zm4 0h-2V7h2v10zm4 0h-2v-4h2v4z\"/>\n",
              "    </g>\n",
              "</svg>\n",
              "  </button>\n",
              "\n",
              "<style>\n",
              "  .colab-df-quickchart {\n",
              "      --bg-color: #E8F0FE;\n",
              "      --fill-color: #1967D2;\n",
              "      --hover-bg-color: #E2EBFA;\n",
              "      --hover-fill-color: #174EA6;\n",
              "      --disabled-fill-color: #AAA;\n",
              "      --disabled-bg-color: #DDD;\n",
              "  }\n",
              "\n",
              "  [theme=dark] .colab-df-quickchart {\n",
              "      --bg-color: #3B4455;\n",
              "      --fill-color: #D2E3FC;\n",
              "      --hover-bg-color: #434B5C;\n",
              "      --hover-fill-color: #FFFFFF;\n",
              "      --disabled-bg-color: #3B4455;\n",
              "      --disabled-fill-color: #666;\n",
              "  }\n",
              "\n",
              "  .colab-df-quickchart {\n",
              "    background-color: var(--bg-color);\n",
              "    border: none;\n",
              "    border-radius: 50%;\n",
              "    cursor: pointer;\n",
              "    display: none;\n",
              "    fill: var(--fill-color);\n",
              "    height: 32px;\n",
              "    padding: 0;\n",
              "    width: 32px;\n",
              "  }\n",
              "\n",
              "  .colab-df-quickchart:hover {\n",
              "    background-color: var(--hover-bg-color);\n",
              "    box-shadow: 0 1px 2px rgba(60, 64, 67, 0.3), 0 1px 3px 1px rgba(60, 64, 67, 0.15);\n",
              "    fill: var(--button-hover-fill-color);\n",
              "  }\n",
              "\n",
              "  .colab-df-quickchart-complete:disabled,\n",
              "  .colab-df-quickchart-complete:disabled:hover {\n",
              "    background-color: var(--disabled-bg-color);\n",
              "    fill: var(--disabled-fill-color);\n",
              "    box-shadow: none;\n",
              "  }\n",
              "\n",
              "  .colab-df-spinner {\n",
              "    border: 2px solid var(--fill-color);\n",
              "    border-color: transparent;\n",
              "    border-bottom-color: var(--fill-color);\n",
              "    animation:\n",
              "      spin 1s steps(1) infinite;\n",
              "  }\n",
              "\n",
              "  @keyframes spin {\n",
              "    0% {\n",
              "      border-color: transparent;\n",
              "      border-bottom-color: var(--fill-color);\n",
              "      border-left-color: var(--fill-color);\n",
              "    }\n",
              "    20% {\n",
              "      border-color: transparent;\n",
              "      border-left-color: var(--fill-color);\n",
              "      border-top-color: var(--fill-color);\n",
              "    }\n",
              "    30% {\n",
              "      border-color: transparent;\n",
              "      border-left-color: var(--fill-color);\n",
              "      border-top-color: var(--fill-color);\n",
              "      border-right-color: var(--fill-color);\n",
              "    }\n",
              "    40% {\n",
              "      border-color: transparent;\n",
              "      border-right-color: var(--fill-color);\n",
              "      border-top-color: var(--fill-color);\n",
              "    }\n",
              "    60% {\n",
              "      border-color: transparent;\n",
              "      border-right-color: var(--fill-color);\n",
              "    }\n",
              "    80% {\n",
              "      border-color: transparent;\n",
              "      border-right-color: var(--fill-color);\n",
              "      border-bottom-color: var(--fill-color);\n",
              "    }\n",
              "    90% {\n",
              "      border-color: transparent;\n",
              "      border-bottom-color: var(--fill-color);\n",
              "    }\n",
              "  }\n",
              "</style>\n",
              "\n",
              "  <script>\n",
              "    async function quickchart(key) {\n",
              "      const quickchartButtonEl =\n",
              "        document.querySelector('#' + key + ' button');\n",
              "      quickchartButtonEl.disabled = true;  // To prevent multiple clicks.\n",
              "      quickchartButtonEl.classList.add('colab-df-spinner');\n",
              "      try {\n",
              "        const charts = await google.colab.kernel.invokeFunction(\n",
              "            'suggestCharts', [key], {});\n",
              "      } catch (error) {\n",
              "        console.error('Error during call to suggestCharts:', error);\n",
              "      }\n",
              "      quickchartButtonEl.classList.remove('colab-df-spinner');\n",
              "      quickchartButtonEl.classList.add('colab-df-quickchart-complete');\n",
              "    }\n",
              "    (() => {\n",
              "      let quickchartButtonEl =\n",
              "        document.querySelector('#df-705eb8fb-da1a-4b9d-a613-9609e1743180 button');\n",
              "      quickchartButtonEl.style.display =\n",
              "        google.colab.kernel.accessAllowed ? 'block' : 'none';\n",
              "    })();\n",
              "  </script>\n",
              "</div>\n",
              "\n",
              "    </div>\n",
              "  </div>\n"
            ],
            "application/vnd.google.colaboratory.intrinsic+json": {
              "type": "dataframe",
              "variable_name": "df",
              "summary": "{\n  \"name\": \"df\",\n  \"rows\": 20640,\n  \"fields\": [\n    {\n      \"column\": \"MedInc\",\n      \"properties\": {\n        \"dtype\": \"number\",\n        \"std\": 1.8998217179452688,\n        \"min\": 0.4999,\n        \"max\": 15.0001,\n        \"num_unique_values\": 12928,\n        \"samples\": [\n          5.0286,\n          2.0433,\n          6.1228\n        ],\n        \"semantic_type\": \"\",\n        \"description\": \"\"\n      }\n    },\n    {\n      \"column\": \"HouseAge\",\n      \"properties\": {\n        \"dtype\": \"number\",\n        \"std\": 12.58555761211165,\n        \"min\": 1.0,\n        \"max\": 52.0,\n        \"num_unique_values\": 52,\n        \"samples\": [\n          35.0,\n          25.0,\n          7.0\n        ],\n        \"semantic_type\": \"\",\n        \"description\": \"\"\n      }\n    },\n    {\n      \"column\": \"AveRooms\",\n      \"properties\": {\n        \"dtype\": \"number\",\n        \"std\": 2.4741731394243187,\n        \"min\": 0.8461538461538461,\n        \"max\": 141.9090909090909,\n        \"num_unique_values\": 19392,\n        \"samples\": [\n          6.111269614835948,\n          5.912820512820513,\n          5.7924528301886795\n        ],\n        \"semantic_type\": \"\",\n        \"description\": \"\"\n      }\n    },\n    {\n      \"column\": \"AveBedrms\",\n      \"properties\": {\n        \"dtype\": \"number\",\n        \"std\": 0.473910856795466,\n        \"min\": 0.3333333333333333,\n        \"max\": 34.06666666666667,\n        \"num_unique_values\": 14233,\n        \"samples\": [\n          0.9906542056074766,\n          1.112099644128114,\n          1.0398230088495575\n        ],\n        \"semantic_type\": \"\",\n        \"description\": \"\"\n      }\n    },\n    {\n      \"column\": \"Population\",\n      \"properties\": {\n        \"dtype\": \"number\",\n        \"std\": 1132.462121765341,\n        \"min\": 3.0,\n        \"max\": 35682.0,\n        \"num_unique_values\": 3888,\n        \"samples\": [\n          4169.0,\n          636.0,\n          3367.0\n        ],\n        \"semantic_type\": \"\",\n        \"description\": \"\"\n      }\n    },\n    {\n      \"column\": \"AveOccup\",\n      \"properties\": {\n        \"dtype\": \"number\",\n        \"std\": 10.386049562213618,\n        \"min\": 0.6923076923076923,\n        \"max\": 1243.3333333333333,\n        \"num_unique_values\": 18841,\n        \"samples\": [\n          2.6939799331103678,\n          3.559375,\n          3.297082228116711\n        ],\n        \"semantic_type\": \"\",\n        \"description\": \"\"\n      }\n    },\n    {\n      \"column\": \"Latitude\",\n      \"properties\": {\n        \"dtype\": \"number\",\n        \"std\": 2.1359523974571153,\n        \"min\": 32.54,\n        \"max\": 41.95,\n        \"num_unique_values\": 862,\n        \"samples\": [\n          33.7,\n          34.41,\n          38.24\n        ],\n        \"semantic_type\": \"\",\n        \"description\": \"\"\n      }\n    },\n    {\n      \"column\": \"Longitude\",\n      \"properties\": {\n        \"dtype\": \"number\",\n        \"std\": 2.0035317235025882,\n        \"min\": -124.35,\n        \"max\": -114.31,\n        \"num_unique_values\": 844,\n        \"samples\": [\n          -118.63,\n          -119.86,\n          -121.26\n        ],\n        \"semantic_type\": \"\",\n        \"description\": \"\"\n      }\n    }\n  ]\n}"
            }
          },
          "metadata": {},
          "execution_count": 13
        }
      ]
    },
    {
      "cell_type": "code",
      "source": [
        "housing.keys()"
      ],
      "metadata": {
        "colab": {
          "base_uri": "https://localhost:8080/"
        },
        "id": "qZSScoWHr1rZ",
        "outputId": "36a5ee14-4205-4759-c099-7d44f4619f9f"
      },
      "execution_count": 38,
      "outputs": [
        {
          "output_type": "execute_result",
          "data": {
            "text/plain": [
              "dict_keys(['data', 'target', 'frame', 'target_names', 'feature_names', 'DESCR'])"
            ]
          },
          "metadata": {},
          "execution_count": 38
        }
      ]
    },
    {
      "cell_type": "code",
      "source": [
        "print(housing.DESCR)"
      ],
      "metadata": {
        "colab": {
          "base_uri": "https://localhost:8080/"
        },
        "id": "PQLEs04MsPC9",
        "outputId": "760abf18-3dbe-4686-dc15-62a872380b42"
      },
      "execution_count": 39,
      "outputs": [
        {
          "output_type": "stream",
          "name": "stdout",
          "text": [
            ".. _california_housing_dataset:\n",
            "\n",
            "California Housing dataset\n",
            "--------------------------\n",
            "\n",
            "**Data Set Characteristics:**\n",
            "\n",
            "    :Number of Instances: 20640\n",
            "\n",
            "    :Number of Attributes: 8 numeric, predictive attributes and the target\n",
            "\n",
            "    :Attribute Information:\n",
            "        - MedInc        median income in block group\n",
            "        - HouseAge      median house age in block group\n",
            "        - AveRooms      average number of rooms per household\n",
            "        - AveBedrms     average number of bedrooms per household\n",
            "        - Population    block group population\n",
            "        - AveOccup      average number of household members\n",
            "        - Latitude      block group latitude\n",
            "        - Longitude     block group longitude\n",
            "\n",
            "    :Missing Attribute Values: None\n",
            "\n",
            "This dataset was obtained from the StatLib repository.\n",
            "https://www.dcc.fc.up.pt/~ltorgo/Regression/cal_housing.html\n",
            "\n",
            "The target variable is the median house value for California districts,\n",
            "expressed in hundreds of thousands of dollars ($100,000).\n",
            "\n",
            "This dataset was derived from the 1990 U.S. census, using one row per census\n",
            "block group. A block group is the smallest geographical unit for which the U.S.\n",
            "Census Bureau publishes sample data (a block group typically has a population\n",
            "of 600 to 3,000 people).\n",
            "\n",
            "A household is a group of people residing within a home. Since the average\n",
            "number of rooms and bedrooms in this dataset are provided per household, these\n",
            "columns may take surprisingly large values for block groups with few households\n",
            "and many empty houses, such as vacation resorts.\n",
            "\n",
            "It can be downloaded/loaded using the\n",
            ":func:`sklearn.datasets.fetch_california_housing` function.\n",
            "\n",
            ".. topic:: References\n",
            "\n",
            "    - Pace, R. Kelley and Ronald Barry, Sparse Spatial Autoregressions,\n",
            "      Statistics and Probability Letters, 33 (1997) 291-297\n",
            "\n"
          ]
        }
      ]
    },
    {
      "cell_type": "code",
      "source": [
        "X = housing.data\n",
        "y = housing.target"
      ],
      "metadata": {
        "id": "ie7a5GRvtj5a"
      },
      "execution_count": 10,
      "outputs": []
    },
    {
      "cell_type": "markdown",
      "source": [
        "#MODELING TECHNIQUES\n",
        "1. Regressao Linear do SKLEARN\n",
        "<https://scikit-learn.org/stable/modules/generated/sklearn.linear_model.LinearRegression.html#sklearn.linear_model.LinearRegression>\n",
        "2. Support Vector Regression do SKLEARN\n",
        "<https://scikit-learn.org/stable/modules/generated/sklearn.svm.SVR.html#sklearn.svm.SVR>\n",
        "3. Decision Tree Regression do XGBOOST\n",
        "<https://xgboost.readthedocs.io/en/latest/python/python_api.html>\n",
        "\n",
        "Modeling Assumptions:\n",
        "Apenas variaveis numericas"
      ],
      "metadata": {
        "id": "ekKNMxnpvZCa"
      }
    },
    {
      "cell_type": "markdown",
      "source": [
        "#TEST DESIGN\n",
        "\n",
        "##Dataset split:\n",
        "Separacao de Train/Test dataset padrao com 20% de massa para teste via metodo SKLEARN\n",
        "\n",
        "##Metrica de avaliacao do modelo:\n",
        "\n",
        "Validacao da metrica MSE e RMSE para penalizar grandes erros de previsao.\n",
        "Utilizando o metodo do SKLEARN\n",
        "<https://scikit-learn.org/stable/modules/generated/sklearn.metrics.mean_squared_error.html#sklearn.metrics.mean_squared_error>\n"
      ],
      "metadata": {
        "id": "JEz0P2p9xkXm"
      }
    },
    {
      "cell_type": "code",
      "source": [
        "X_train, X_test, y_train, y_test = train_test_split(X, y, test_size=0.2, random_state=36)"
      ],
      "metadata": {
        "id": "XQBT8Txxx4qW"
      },
      "execution_count": 11,
      "outputs": []
    },
    {
      "cell_type": "markdown",
      "source": [
        "## TECNICA 1. REGRESSAO LINEAR"
      ],
      "metadata": {
        "id": "vXqEfgC97aZD"
      }
    },
    {
      "cell_type": "code",
      "source": [
        "regLinear = LinearRegression().fit(X_train, y_train)"
      ],
      "metadata": {
        "id": "ORw4XbCnw6DV"
      },
      "execution_count": 12,
      "outputs": []
    },
    {
      "cell_type": "code",
      "source": [
        "yPredLinear = regLinear.predict(X_test)"
      ],
      "metadata": {
        "id": "MQhWZVOk1BN1"
      },
      "execution_count": 13,
      "outputs": []
    },
    {
      "cell_type": "code",
      "source": [
        "print(yPredLinear)"
      ],
      "metadata": {
        "colab": {
          "base_uri": "https://localhost:8080/"
        },
        "id": "3u89VdDC5jLe",
        "outputId": "fa5e4981-5c28-477a-f43d-6c0d245787ee"
      },
      "execution_count": 14,
      "outputs": [
        {
          "output_type": "stream",
          "name": "stdout",
          "text": [
            "[1.74752402 0.89910994 2.45065311 ... 2.64918195 0.59914103 0.71772807]\n"
          ]
        }
      ]
    },
    {
      "cell_type": "code",
      "source": [
        "MSE = mean_squared_error(y_test, yPredLinear)\n",
        "RMSE = mean_squared_error(y_test, yPredLinear, squared=False)"
      ],
      "metadata": {
        "id": "jXOHBxxT5z7i"
      },
      "execution_count": 37,
      "outputs": []
    },
    {
      "cell_type": "code",
      "source": [
        "print(\"MSE:\", MSE)\n",
        "print(\"RMSE:\", np.sqrt(MSE))"
      ],
      "metadata": {
        "colab": {
          "base_uri": "https://localhost:8080/"
        },
        "id": "8QHAlxBH6RXK",
        "outputId": "7420c6a0-64aa-4706-98bd-2a1efbbdc167"
      },
      "execution_count": 47,
      "outputs": [
        {
          "output_type": "stream",
          "name": "stdout",
          "text": [
            "MSE: 0.5319448504398667\n",
            "RMSE: 0.7293454945633563\n"
          ]
        }
      ]
    },
    {
      "cell_type": "markdown",
      "source": [
        "##TECNICA 2. SVR"
      ],
      "metadata": {
        "id": "X19qC1FL7EMC"
      }
    },
    {
      "cell_type": "code",
      "source": [
        "regSVR = SVR().fit(X_train, y_train)"
      ],
      "metadata": {
        "id": "swkT183K7LcL"
      },
      "execution_count": 15,
      "outputs": []
    },
    {
      "cell_type": "code",
      "source": [
        "ySVR = regSVR.predict(X_test)"
      ],
      "metadata": {
        "id": "rzbCyV768IBm"
      },
      "execution_count": 19,
      "outputs": []
    },
    {
      "cell_type": "code",
      "source": [
        "print(ySVR)"
      ],
      "metadata": {
        "colab": {
          "base_uri": "https://localhost:8080/"
        },
        "id": "j3vC6kVI8ZKd",
        "outputId": "32b6229b-c65c-41a3-d428-3893efdc4128"
      },
      "execution_count": 39,
      "outputs": [
        {
          "output_type": "stream",
          "name": "stdout",
          "text": [
            "[1.7069352  1.85914436 1.75901173 ... 1.78804996 1.78510084 1.8663997 ]\n"
          ]
        }
      ]
    },
    {
      "cell_type": "code",
      "source": [
        "MSESVR = mean_squared_error(y_test, ySVR)\n",
        "RMSESVR = mean_squared_error(y_test, ySVR)"
      ],
      "metadata": {
        "id": "L9-CfZp28pq6"
      },
      "execution_count": 20,
      "outputs": []
    },
    {
      "cell_type": "code",
      "source": [
        "print(\"MSESVR:\", MSESVR)\n",
        "print(\"RMSESVR:\", RMSESVR)"
      ],
      "metadata": {
        "colab": {
          "base_uri": "https://localhost:8080/"
        },
        "id": "RzRLE_UD9Ho0",
        "outputId": "98c2f798-0f22-43a2-8a2c-052fad1678a0"
      },
      "execution_count": 42,
      "outputs": [
        {
          "output_type": "stream",
          "name": "stdout",
          "text": [
            "MSESVR: 1.3202584220271705\n",
            "RMSESVR: 1.3202584220271705\n"
          ]
        }
      ]
    },
    {
      "cell_type": "markdown",
      "source": [
        "##TECNICA 3. DECISION TREE REGRESSION (XGBOOST)"
      ],
      "metadata": {
        "id": "CacLL4tX9YrY"
      }
    },
    {
      "cell_type": "code",
      "source": [
        "regXGB = xgb.XGBRegressor().fit(X_train, y_train)"
      ],
      "metadata": {
        "id": "XzJmsYm091lT"
      },
      "execution_count": 16,
      "outputs": []
    },
    {
      "cell_type": "code",
      "source": [
        "yXGB = regXGB.predict(X_test)"
      ],
      "metadata": {
        "id": "Tu3ewpVu-WSm"
      },
      "execution_count": 21,
      "outputs": []
    },
    {
      "cell_type": "code",
      "source": [
        "MSEXGB = mean_squared_error(y_test, yXGB)\n",
        "RMSEXGB = mean_squared_error(y_test, yXGB)"
      ],
      "metadata": {
        "id": "3PEJBb6P-gYz"
      },
      "execution_count": 22,
      "outputs": []
    },
    {
      "cell_type": "code",
      "source": [
        "print(\"MSE XGB:\", MSEXGB)\n",
        "print(\"RMSE XGB:\", np.sqrt(RMSEXGB))"
      ],
      "metadata": {
        "colab": {
          "base_uri": "https://localhost:8080/"
        },
        "id": "61iEwhzB-rt3",
        "outputId": "89d4f8d9-6e0c-4cd6-aed8-2406467b969e"
      },
      "execution_count": 36,
      "outputs": [
        {
          "output_type": "stream",
          "name": "stdout",
          "text": [
            "MSE XGB: 0.218119337530431\n",
            "RMSE XGB: 0.4670324801664559\n"
          ]
        }
      ]
    },
    {
      "cell_type": "markdown",
      "source": [
        "\n",
        "\n",
        "#OTIMIZACAO DE HYPERPARAMETROS\n",
        "\n",
        "## UTILIZANDO O METODO GridSearch\n",
        "<http://scikit-learn.org/stable/modules/generated/sklearn.model_selection.GridSearchCV.html#sklearn.model_selection.GridSearchCV>"
      ],
      "metadata": {
        "id": "7zld5CHWBBQ1"
      }
    },
    {
      "cell_type": "code",
      "source": [
        "regXGB.get_params().keys()"
      ],
      "metadata": {
        "colab": {
          "base_uri": "https://localhost:8080/"
        },
        "id": "RrnAhjfmC5g8",
        "outputId": "2dc5ba17-5427-453b-8127-f31b54c00962"
      },
      "execution_count": 35,
      "outputs": [
        {
          "output_type": "execute_result",
          "data": {
            "text/plain": [
              "dict_keys(['objective', 'base_score', 'booster', 'callbacks', 'colsample_bylevel', 'colsample_bynode', 'colsample_bytree', 'device', 'early_stopping_rounds', 'enable_categorical', 'eval_metric', 'feature_types', 'gamma', 'grow_policy', 'importance_type', 'interaction_constraints', 'learning_rate', 'max_bin', 'max_cat_threshold', 'max_cat_to_onehot', 'max_delta_step', 'max_depth', 'max_leaves', 'min_child_weight', 'missing', 'monotone_constraints', 'multi_strategy', 'n_estimators', 'n_jobs', 'num_parallel_tree', 'random_state', 'reg_alpha', 'reg_lambda', 'sampling_method', 'scale_pos_weight', 'subsample', 'tree_method', 'validate_parameters', 'verbosity'])"
            ]
          },
          "metadata": {},
          "execution_count": 35
        }
      ]
    },
    {
      "cell_type": "code",
      "source": [
        "Parameters = { \"max_depth\": [5, 6, 7],\n",
        "               \"learning_rate\": [0.1, 0.2, 0.3],\n",
        "               \"objective\": ['squaredeerror'],\n",
        "               \"booster\": ['gbtree'],\n",
        "               \"n_jobs\": [5],\n",
        "               \"gamma\": [0,1],\n",
        "               \"min_child_weight\": [1, 3],\n",
        "               \"max_delta_step\": [0, 1],\n",
        "               \"subsample\": [0.5, 1]\n",
        "               }"
      ],
      "metadata": {
        "id": "Xa_K7AvfEWc4"
      },
      "execution_count": 34,
      "outputs": []
    },
    {
      "cell_type": "code",
      "source": [
        "xgbGrid = GridSearchCV(xgb.XGBRegressor(),Parameters, refit='neg_mean_squared_error', verbose=True)"
      ],
      "metadata": {
        "id": "L1Ahav0HG-7R"
      },
      "execution_count": 32,
      "outputs": []
    },
    {
      "cell_type": "code",
      "source": [
        "xgbGridModel = xgbGrid.fit(X_train, y_train)"
      ],
      "metadata": {
        "colab": {
          "base_uri": "https://localhost:8080/",
          "height": 1000
        },
        "id": "mUdOgd6KLaXs",
        "outputId": "d5e5497e-f9d2-4b6b-f3fe-2b32ddb87207"
      },
      "execution_count": 43,
      "outputs": [
        {
          "output_type": "stream",
          "name": "stdout",
          "text": [
            "Fitting 5 folds for each of 144 candidates, totalling 720 fits\n"
          ]
        },
        {
          "output_type": "error",
          "ename": "ValueError",
          "evalue": "\nAll the 720 fits failed.\nIt is very likely that your model is misconfigured.\nYou can try to debug the error by setting error_score='raise'.\n\nBelow are more details about the failures:\n--------------------------------------------------------------------------------\n5 fits failed with the following error:\nTraceback (most recent call last):\n  File \"/usr/local/lib/python3.10/dist-packages/sklearn/model_selection/_validation.py\", line 686, in _fit_and_score\n    estimator.fit(X_train, y_train, **fit_params)\n  File \"/usr/local/lib/python3.10/dist-packages/xgboost/core.py\", line 730, in inner_f\n    return func(**kwargs)\n  File \"/usr/local/lib/python3.10/dist-packages/xgboost/sklearn.py\", line 1090, in fit\n    self._Booster = train(\n  File \"/usr/local/lib/python3.10/dist-packages/xgboost/core.py\", line 730, in inner_f\n    return func(**kwargs)\n  File \"/usr/local/lib/python3.10/dist-packages/xgboost/training.py\", line 181, in train\n    bst.update(dtrain, i, obj)\n  File \"/usr/local/lib/python3.10/dist-packages/xgboost/core.py\", line 2050, in update\n    _check_call(\n  File \"/usr/local/lib/python3.10/dist-packages/xgboost/core.py\", line 282, in _check_call\n    raise XGBoostError(py_str(_LIB.XGBGetLastError()))\nxgboost.core.XGBoostError: [19:44:39] /workspace/src/objective/objective.cc:27: Unknown objective function: `squaredeerror`\nObjective candidate: rank:ndcg\nObjective candidate: rank:pairwise\nObjective candidate: rank:map\nObjective candidate: survival:aft\nObjective candidate: binary:hinge\nObjective candidate: multi:softmax\nObjective candidate: multi:softprob\nObjective candidate: reg:quantileerror\nObjective candidate: reg:squarederror\nObjective candidate: reg:squaredlogerror\nObjective candidate: reg:logistic\nObjective candidate: binary:logistic\nObjective candidate: binary:logitraw\nObjective candidate: reg:linear\nObjective candidate: reg:pseudohubererror\nObjective candidate: count:poisson\nObjective candidate: survival:cox\nObjective candidate: reg:gamma\nObjective candidate: reg:tweedie\nObjective candidate: reg:absoluteerror\n\nStack trace:\n  [bt] (0) /usr/local/lib/python3.10/dist-packages/xgboost/lib/libxgboost.so(+0x1ba24e) [0x7ebdc8b2024e]\n  [bt] (1) /usr/local/lib/python3.10/dist-packages/xgboost/lib/libxgboost.so(+0x60c6ce) [0x7ebdc8f726ce]\n  [bt] (2) /usr/local/lib/python3.10/dist-packages/xgboost/lib/libxgboost.so(+0x4b9c3f) [0x7ebdc8e1fc3f]\n  [bt] (3) /usr/local/lib/python3.10/dist-packages/xgboost/lib/libxgboost.so(+0x4cccd3) [0x7ebdc8e32cd3]\n  [bt] (4) /usr/local/lib/python3.10/dist-packages/xgboost/lib/libxgboost.so(+0x4c5268) [0x7ebdc8e2b268]\n  [bt] (5) /usr/local/lib/python3.10/dist-packages/xgboost/lib/libxgboost.so(XGBoosterUpdateOneIter+0x70) [0x7ebdc8ac7ef0]\n  [bt] (6) /lib/x86_64-linux-gnu/libffi.so.8(+0x7e2e) [0x7ebe31e94e2e]\n  [bt] (7) /lib/x86_64-linux-gnu/libffi.so.8(+0x4493) [0x7ebe31e91493]\n  [bt] (8) /usr/lib/python3.10/lib-dynload/_ctypes.cpython-310-x86_64-linux-gnu.so(+0xa3e9) [0x7ebe31eba3e9]\n\n\n\n--------------------------------------------------------------------------------\n22 fits failed with the following error:\nTraceback (most recent call last):\n  File \"/usr/local/lib/python3.10/dist-packages/sklearn/model_selection/_validation.py\", line 686, in _fit_and_score\n    estimator.fit(X_train, y_train, **fit_params)\n  File \"/usr/local/lib/python3.10/dist-packages/xgboost/core.py\", line 730, in inner_f\n    return func(**kwargs)\n  File \"/usr/local/lib/python3.10/dist-packages/xgboost/sklearn.py\", line 1090, in fit\n    self._Booster = train(\n  File \"/usr/local/lib/python3.10/dist-packages/xgboost/core.py\", line 730, in inner_f\n    return func(**kwargs)\n  File \"/usr/local/lib/python3.10/dist-packages/xgboost/training.py\", line 181, in train\n    bst.update(dtrain, i, obj)\n  File \"/usr/local/lib/python3.10/dist-packages/xgboost/core.py\", line 2050, in update\n    _check_call(\n  File \"/usr/local/lib/python3.10/dist-packages/xgboost/core.py\", line 282, in _check_call\n    raise XGBoostError(py_str(_LIB.XGBGetLastError()))\nxgboost.core.XGBoostError: [19:44:40] /workspace/src/objective/objective.cc:27: Unknown objective function: `squaredeerror`\nObjective candidate: rank:ndcg\nObjective candidate: rank:pairwise\nObjective candidate: rank:map\nObjective candidate: survival:aft\nObjective candidate: binary:hinge\nObjective candidate: multi:softmax\nObjective candidate: multi:softprob\nObjective candidate: reg:quantileerror\nObjective candidate: reg:squarederror\nObjective candidate: reg:squaredlogerror\nObjective candidate: reg:logistic\nObjective candidate: binary:logistic\nObjective candidate: binary:logitraw\nObjective candidate: reg:linear\nObjective candidate: reg:pseudohubererror\nObjective candidate: count:poisson\nObjective candidate: survival:cox\nObjective candidate: reg:gamma\nObjective candidate: reg:tweedie\nObjective candidate: reg:absoluteerror\n\nStack trace:\n  [bt] (0) /usr/local/lib/python3.10/dist-packages/xgboost/lib/libxgboost.so(+0x1ba24e) [0x7ebdc8b2024e]\n  [bt] (1) /usr/local/lib/python3.10/dist-packages/xgboost/lib/libxgboost.so(+0x60c6ce) [0x7ebdc8f726ce]\n  [bt] (2) /usr/local/lib/python3.10/dist-packages/xgboost/lib/libxgboost.so(+0x4b9c3f) [0x7ebdc8e1fc3f]\n  [bt] (3) /usr/local/lib/python3.10/dist-packages/xgboost/lib/libxgboost.so(+0x4cccd3) [0x7ebdc8e32cd3]\n  [bt] (4) /usr/local/lib/python3.10/dist-packages/xgboost/lib/libxgboost.so(+0x4c5268) [0x7ebdc8e2b268]\n  [bt] (5) /usr/local/lib/python3.10/dist-packages/xgboost/lib/libxgboost.so(XGBoosterUpdateOneIter+0x70) [0x7ebdc8ac7ef0]\n  [bt] (6) /lib/x86_64-linux-gnu/libffi.so.8(+0x7e2e) [0x7ebe31e94e2e]\n  [bt] (7) /lib/x86_64-linux-gnu/libffi.so.8(+0x4493) [0x7ebe31e91493]\n  [bt] (8) /usr/lib/python3.10/lib-dynload/_ctypes.cpython-310-x86_64-linux-gnu.so(+0xa3e9) [0x7ebe31eba3e9]\n\n\n\n--------------------------------------------------------------------------------\n41 fits failed with the following error:\nTraceback (most recent call last):\n  File \"/usr/local/lib/python3.10/dist-packages/sklearn/model_selection/_validation.py\", line 686, in _fit_and_score\n    estimator.fit(X_train, y_train, **fit_params)\n  File \"/usr/local/lib/python3.10/dist-packages/xgboost/core.py\", line 730, in inner_f\n    return func(**kwargs)\n  File \"/usr/local/lib/python3.10/dist-packages/xgboost/sklearn.py\", line 1090, in fit\n    self._Booster = train(\n  File \"/usr/local/lib/python3.10/dist-packages/xgboost/core.py\", line 730, in inner_f\n    return func(**kwargs)\n  File \"/usr/local/lib/python3.10/dist-packages/xgboost/training.py\", line 181, in train\n    bst.update(dtrain, i, obj)\n  File \"/usr/local/lib/python3.10/dist-packages/xgboost/core.py\", line 2050, in update\n    _check_call(\n  File \"/usr/local/lib/python3.10/dist-packages/xgboost/core.py\", line 282, in _check_call\n    raise XGBoostError(py_str(_LIB.XGBGetLastError()))\nxgboost.core.XGBoostError: [19:44:41] /workspace/src/objective/objective.cc:27: Unknown objective function: `squaredeerror`\nObjective candidate: rank:ndcg\nObjective candidate: rank:pairwise\nObjective candidate: rank:map\nObjective candidate: survival:aft\nObjective candidate: binary:hinge\nObjective candidate: multi:softmax\nObjective candidate: multi:softprob\nObjective candidate: reg:quantileerror\nObjective candidate: reg:squarederror\nObjective candidate: reg:squaredlogerror\nObjective candidate: reg:logistic\nObjective candidate: binary:logistic\nObjective candidate: binary:logitraw\nObjective candidate: reg:linear\nObjective candidate: reg:pseudohubererror\nObjective candidate: count:poisson\nObjective candidate: survival:cox\nObjective candidate: reg:gamma\nObjective candidate: reg:tweedie\nObjective candidate: reg:absoluteerror\n\nStack trace:\n  [bt] (0) /usr/local/lib/python3.10/dist-packages/xgboost/lib/libxgboost.so(+0x1ba24e) [0x7ebdc8b2024e]\n  [bt] (1) /usr/local/lib/python3.10/dist-packages/xgboost/lib/libxgboost.so(+0x60c6ce) [0x7ebdc8f726ce]\n  [bt] (2) /usr/local/lib/python3.10/dist-packages/xgboost/lib/libxgboost.so(+0x4b9c3f) [0x7ebdc8e1fc3f]\n  [bt] (3) /usr/local/lib/python3.10/dist-packages/xgboost/lib/libxgboost.so(+0x4cccd3) [0x7ebdc8e32cd3]\n  [bt] (4) /usr/local/lib/python3.10/dist-packages/xgboost/lib/libxgboost.so(+0x4c5268) [0x7ebdc8e2b268]\n  [bt] (5) /usr/local/lib/python3.10/dist-packages/xgboost/lib/libxgboost.so(XGBoosterUpdateOneIter+0x70) [0x7ebdc8ac7ef0]\n  [bt] (6) /lib/x86_64-linux-gnu/libffi.so.8(+0x7e2e) [0x7ebe31e94e2e]\n  [bt] (7) /lib/x86_64-linux-gnu/libffi.so.8(+0x4493) [0x7ebe31e91493]\n  [bt] (8) /usr/lib/python3.10/lib-dynload/_ctypes.cpython-310-x86_64-linux-gnu.so(+0xa3e9) [0x7ebe31eba3e9]\n\n\n\n--------------------------------------------------------------------------------\n41 fits failed with the following error:\nTraceback (most recent call last):\n  File \"/usr/local/lib/python3.10/dist-packages/sklearn/model_selection/_validation.py\", line 686, in _fit_and_score\n    estimator.fit(X_train, y_train, **fit_params)\n  File \"/usr/local/lib/python3.10/dist-packages/xgboost/core.py\", line 730, in inner_f\n    return func(**kwargs)\n  File \"/usr/local/lib/python3.10/dist-packages/xgboost/sklearn.py\", line 1090, in fit\n    self._Booster = train(\n  File \"/usr/local/lib/python3.10/dist-packages/xgboost/core.py\", line 730, in inner_f\n    return func(**kwargs)\n  File \"/usr/local/lib/python3.10/dist-packages/xgboost/training.py\", line 181, in train\n    bst.update(dtrain, i, obj)\n  File \"/usr/local/lib/python3.10/dist-packages/xgboost/core.py\", line 2050, in update\n    _check_call(\n  File \"/usr/local/lib/python3.10/dist-packages/xgboost/core.py\", line 282, in _check_call\n    raise XGBoostError(py_str(_LIB.XGBGetLastError()))\nxgboost.core.XGBoostError: [19:44:42] /workspace/src/objective/objective.cc:27: Unknown objective function: `squaredeerror`\nObjective candidate: rank:ndcg\nObjective candidate: rank:pairwise\nObjective candidate: rank:map\nObjective candidate: survival:aft\nObjective candidate: binary:hinge\nObjective candidate: multi:softmax\nObjective candidate: multi:softprob\nObjective candidate: reg:quantileerror\nObjective candidate: reg:squarederror\nObjective candidate: reg:squaredlogerror\nObjective candidate: reg:logistic\nObjective candidate: binary:logistic\nObjective candidate: binary:logitraw\nObjective candidate: reg:linear\nObjective candidate: reg:pseudohubererror\nObjective candidate: count:poisson\nObjective candidate: survival:cox\nObjective candidate: reg:gamma\nObjective candidate: reg:tweedie\nObjective candidate: reg:absoluteerror\n\nStack trace:\n  [bt] (0) /usr/local/lib/python3.10/dist-packages/xgboost/lib/libxgboost.so(+0x1ba24e) [0x7ebdc8b2024e]\n  [bt] (1) /usr/local/lib/python3.10/dist-packages/xgboost/lib/libxgboost.so(+0x60c6ce) [0x7ebdc8f726ce]\n  [bt] (2) /usr/local/lib/python3.10/dist-packages/xgboost/lib/libxgboost.so(+0x4b9c3f) [0x7ebdc8e1fc3f]\n  [bt] (3) /usr/local/lib/python3.10/dist-packages/xgboost/lib/libxgboost.so(+0x4cccd3) [0x7ebdc8e32cd3]\n  [bt] (4) /usr/local/lib/python3.10/dist-packages/xgboost/lib/libxgboost.so(+0x4c5268) [0x7ebdc8e2b268]\n  [bt] (5) /usr/local/lib/python3.10/dist-packages/xgboost/lib/libxgboost.so(XGBoosterUpdateOneIter+0x70) [0x7ebdc8ac7ef0]\n  [bt] (6) /lib/x86_64-linux-gnu/libffi.so.8(+0x7e2e) [0x7ebe31e94e2e]\n  [bt] (7) /lib/x86_64-linux-gnu/libffi.so.8(+0x4493) [0x7ebe31e91493]\n  [bt] (8) /usr/lib/python3.10/lib-dynload/_ctypes.cpython-310-x86_64-linux-gnu.so(+0xa3e9) [0x7ebe31eba3e9]\n\n\n\n--------------------------------------------------------------------------------\n42 fits failed with the following error:\nTraceback (most recent call last):\n  File \"/usr/local/lib/python3.10/dist-packages/sklearn/model_selection/_validation.py\", line 686, in _fit_and_score\n    estimator.fit(X_train, y_train, **fit_params)\n  File \"/usr/local/lib/python3.10/dist-packages/xgboost/core.py\", line 730, in inner_f\n    return func(**kwargs)\n  File \"/usr/local/lib/python3.10/dist-packages/xgboost/sklearn.py\", line 1090, in fit\n    self._Booster = train(\n  File \"/usr/local/lib/python3.10/dist-packages/xgboost/core.py\", line 730, in inner_f\n    return func(**kwargs)\n  File \"/usr/local/lib/python3.10/dist-packages/xgboost/training.py\", line 181, in train\n    bst.update(dtrain, i, obj)\n  File \"/usr/local/lib/python3.10/dist-packages/xgboost/core.py\", line 2050, in update\n    _check_call(\n  File \"/usr/local/lib/python3.10/dist-packages/xgboost/core.py\", line 282, in _check_call\n    raise XGBoostError(py_str(_LIB.XGBGetLastError()))\nxgboost.core.XGBoostError: [19:44:43] /workspace/src/objective/objective.cc:27: Unknown objective function: `squaredeerror`\nObjective candidate: rank:ndcg\nObjective candidate: rank:pairwise\nObjective candidate: rank:map\nObjective candidate: survival:aft\nObjective candidate: binary:hinge\nObjective candidate: multi:softmax\nObjective candidate: multi:softprob\nObjective candidate: reg:quantileerror\nObjective candidate: reg:squarederror\nObjective candidate: reg:squaredlogerror\nObjective candidate: reg:logistic\nObjective candidate: binary:logistic\nObjective candidate: binary:logitraw\nObjective candidate: reg:linear\nObjective candidate: reg:pseudohubererror\nObjective candidate: count:poisson\nObjective candidate: survival:cox\nObjective candidate: reg:gamma\nObjective candidate: reg:tweedie\nObjective candidate: reg:absoluteerror\n\nStack trace:\n  [bt] (0) /usr/local/lib/python3.10/dist-packages/xgboost/lib/libxgboost.so(+0x1ba24e) [0x7ebdc8b2024e]\n  [bt] (1) /usr/local/lib/python3.10/dist-packages/xgboost/lib/libxgboost.so(+0x60c6ce) [0x7ebdc8f726ce]\n  [bt] (2) /usr/local/lib/python3.10/dist-packages/xgboost/lib/libxgboost.so(+0x4b9c3f) [0x7ebdc8e1fc3f]\n  [bt] (3) /usr/local/lib/python3.10/dist-packages/xgboost/lib/libxgboost.so(+0x4cccd3) [0x7ebdc8e32cd3]\n  [bt] (4) /usr/local/lib/python3.10/dist-packages/xgboost/lib/libxgboost.so(+0x4c5268) [0x7ebdc8e2b268]\n  [bt] (5) /usr/local/lib/python3.10/dist-packages/xgboost/lib/libxgboost.so(XGBoosterUpdateOneIter+0x70) [0x7ebdc8ac7ef0]\n  [bt] (6) /lib/x86_64-linux-gnu/libffi.so.8(+0x7e2e) [0x7ebe31e94e2e]\n  [bt] (7) /lib/x86_64-linux-gnu/libffi.so.8(+0x4493) [0x7ebe31e91493]\n  [bt] (8) /usr/lib/python3.10/lib-dynload/_ctypes.cpython-310-x86_64-linux-gnu.so(+0xa3e9) [0x7ebe31eba3e9]\n\n\n\n--------------------------------------------------------------------------------\n42 fits failed with the following error:\nTraceback (most recent call last):\n  File \"/usr/local/lib/python3.10/dist-packages/sklearn/model_selection/_validation.py\", line 686, in _fit_and_score\n    estimator.fit(X_train, y_train, **fit_params)\n  File \"/usr/local/lib/python3.10/dist-packages/xgboost/core.py\", line 730, in inner_f\n    return func(**kwargs)\n  File \"/usr/local/lib/python3.10/dist-packages/xgboost/sklearn.py\", line 1090, in fit\n    self._Booster = train(\n  File \"/usr/local/lib/python3.10/dist-packages/xgboost/core.py\", line 730, in inner_f\n    return func(**kwargs)\n  File \"/usr/local/lib/python3.10/dist-packages/xgboost/training.py\", line 181, in train\n    bst.update(dtrain, i, obj)\n  File \"/usr/local/lib/python3.10/dist-packages/xgboost/core.py\", line 2050, in update\n    _check_call(\n  File \"/usr/local/lib/python3.10/dist-packages/xgboost/core.py\", line 282, in _check_call\n    raise XGBoostError(py_str(_LIB.XGBGetLastError()))\nxgboost.core.XGBoostError: [19:44:44] /workspace/src/objective/objective.cc:27: Unknown objective function: `squaredeerror`\nObjective candidate: rank:ndcg\nObjective candidate: rank:pairwise\nObjective candidate: rank:map\nObjective candidate: survival:aft\nObjective candidate: binary:hinge\nObjective candidate: multi:softmax\nObjective candidate: multi:softprob\nObjective candidate: reg:quantileerror\nObjective candidate: reg:squarederror\nObjective candidate: reg:squaredlogerror\nObjective candidate: reg:logistic\nObjective candidate: binary:logistic\nObjective candidate: binary:logitraw\nObjective candidate: reg:linear\nObjective candidate: reg:pseudohubererror\nObjective candidate: count:poisson\nObjective candidate: survival:cox\nObjective candidate: reg:gamma\nObjective candidate: reg:tweedie\nObjective candidate: reg:absoluteerror\n\nStack trace:\n  [bt] (0) /usr/local/lib/python3.10/dist-packages/xgboost/lib/libxgboost.so(+0x1ba24e) [0x7ebdc8b2024e]\n  [bt] (1) /usr/local/lib/python3.10/dist-packages/xgboost/lib/libxgboost.so(+0x60c6ce) [0x7ebdc8f726ce]\n  [bt] (2) /usr/local/lib/python3.10/dist-packages/xgboost/lib/libxgboost.so(+0x4b9c3f) [0x7ebdc8e1fc3f]\n  [bt] (3) /usr/local/lib/python3.10/dist-packages/xgboost/lib/libxgboost.so(+0x4cccd3) [0x7ebdc8e32cd3]\n  [bt] (4) /usr/local/lib/python3.10/dist-packages/xgboost/lib/libxgboost.so(+0x4c5268) [0x7ebdc8e2b268]\n  [bt] (5) /usr/local/lib/python3.10/dist-packages/xgboost/lib/libxgboost.so(XGBoosterUpdateOneIter+0x70) [0x7ebdc8ac7ef0]\n  [bt] (6) /lib/x86_64-linux-gnu/libffi.so.8(+0x7e2e) [0x7ebe31e94e2e]\n  [bt] (7) /lib/x86_64-linux-gnu/libffi.so.8(+0x4493) [0x7ebe31e91493]\n  [bt] (8) /usr/lib/python3.10/lib-dynload/_ctypes.cpython-310-x86_64-linux-gnu.so(+0xa3e9) [0x7ebe31eba3e9]\n\n\n\n--------------------------------------------------------------------------------\n41 fits failed with the following error:\nTraceback (most recent call last):\n  File \"/usr/local/lib/python3.10/dist-packages/sklearn/model_selection/_validation.py\", line 686, in _fit_and_score\n    estimator.fit(X_train, y_train, **fit_params)\n  File \"/usr/local/lib/python3.10/dist-packages/xgboost/core.py\", line 730, in inner_f\n    return func(**kwargs)\n  File \"/usr/local/lib/python3.10/dist-packages/xgboost/sklearn.py\", line 1090, in fit\n    self._Booster = train(\n  File \"/usr/local/lib/python3.10/dist-packages/xgboost/core.py\", line 730, in inner_f\n    return func(**kwargs)\n  File \"/usr/local/lib/python3.10/dist-packages/xgboost/training.py\", line 181, in train\n    bst.update(dtrain, i, obj)\n  File \"/usr/local/lib/python3.10/dist-packages/xgboost/core.py\", line 2050, in update\n    _check_call(\n  File \"/usr/local/lib/python3.10/dist-packages/xgboost/core.py\", line 282, in _check_call\n    raise XGBoostError(py_str(_LIB.XGBGetLastError()))\nxgboost.core.XGBoostError: [19:44:45] /workspace/src/objective/objective.cc:27: Unknown objective function: `squaredeerror`\nObjective candidate: rank:ndcg\nObjective candidate: rank:pairwise\nObjective candidate: rank:map\nObjective candidate: survival:aft\nObjective candidate: binary:hinge\nObjective candidate: multi:softmax\nObjective candidate: multi:softprob\nObjective candidate: reg:quantileerror\nObjective candidate: reg:squarederror\nObjective candidate: reg:squaredlogerror\nObjective candidate: reg:logistic\nObjective candidate: binary:logistic\nObjective candidate: binary:logitraw\nObjective candidate: reg:linear\nObjective candidate: reg:pseudohubererror\nObjective candidate: count:poisson\nObjective candidate: survival:cox\nObjective candidate: reg:gamma\nObjective candidate: reg:tweedie\nObjective candidate: reg:absoluteerror\n\nStack trace:\n  [bt] (0) /usr/local/lib/python3.10/dist-packages/xgboost/lib/libxgboost.so(+0x1ba24e) [0x7ebdc8b2024e]\n  [bt] (1) /usr/local/lib/python3.10/dist-packages/xgboost/lib/libxgboost.so(+0x60c6ce) [0x7ebdc8f726ce]\n  [bt] (2) /usr/local/lib/python3.10/dist-packages/xgboost/lib/libxgboost.so(+0x4b9c3f) [0x7ebdc8e1fc3f]\n  [bt] (3) /usr/local/lib/python3.10/dist-packages/xgboost/lib/libxgboost.so(+0x4cccd3) [0x7ebdc8e32cd3]\n  [bt] (4) /usr/local/lib/python3.10/dist-packages/xgboost/lib/libxgboost.so(+0x4c5268) [0x7ebdc8e2b268]\n  [bt] (5) /usr/local/lib/python3.10/dist-packages/xgboost/lib/libxgboost.so(XGBoosterUpdateOneIter+0x70) [0x7ebdc8ac7ef0]\n  [bt] (6) /lib/x86_64-linux-gnu/libffi.so.8(+0x7e2e) [0x7ebe31e94e2e]\n  [bt] (7) /lib/x86_64-linux-gnu/libffi.so.8(+0x4493) [0x7ebe31e91493]\n  [bt] (8) /usr/lib/python3.10/lib-dynload/_ctypes.cpython-310-x86_64-linux-gnu.so(+0xa3e9) [0x7ebe31eba3e9]\n\n\n\n--------------------------------------------------------------------------------\n42 fits failed with the following error:\nTraceback (most recent call last):\n  File \"/usr/local/lib/python3.10/dist-packages/sklearn/model_selection/_validation.py\", line 686, in _fit_and_score\n    estimator.fit(X_train, y_train, **fit_params)\n  File \"/usr/local/lib/python3.10/dist-packages/xgboost/core.py\", line 730, in inner_f\n    return func(**kwargs)\n  File \"/usr/local/lib/python3.10/dist-packages/xgboost/sklearn.py\", line 1090, in fit\n    self._Booster = train(\n  File \"/usr/local/lib/python3.10/dist-packages/xgboost/core.py\", line 730, in inner_f\n    return func(**kwargs)\n  File \"/usr/local/lib/python3.10/dist-packages/xgboost/training.py\", line 181, in train\n    bst.update(dtrain, i, obj)\n  File \"/usr/local/lib/python3.10/dist-packages/xgboost/core.py\", line 2050, in update\n    _check_call(\n  File \"/usr/local/lib/python3.10/dist-packages/xgboost/core.py\", line 282, in _check_call\n    raise XGBoostError(py_str(_LIB.XGBGetLastError()))\nxgboost.core.XGBoostError: [19:44:46] /workspace/src/objective/objective.cc:27: Unknown objective function: `squaredeerror`\nObjective candidate: rank:ndcg\nObjective candidate: rank:pairwise\nObjective candidate: rank:map\nObjective candidate: survival:aft\nObjective candidate: binary:hinge\nObjective candidate: multi:softmax\nObjective candidate: multi:softprob\nObjective candidate: reg:quantileerror\nObjective candidate: reg:squarederror\nObjective candidate: reg:squaredlogerror\nObjective candidate: reg:logistic\nObjective candidate: binary:logistic\nObjective candidate: binary:logitraw\nObjective candidate: reg:linear\nObjective candidate: reg:pseudohubererror\nObjective candidate: count:poisson\nObjective candidate: survival:cox\nObjective candidate: reg:gamma\nObjective candidate: reg:tweedie\nObjective candidate: reg:absoluteerror\n\nStack trace:\n  [bt] (0) /usr/local/lib/python3.10/dist-packages/xgboost/lib/libxgboost.so(+0x1ba24e) [0x7ebdc8b2024e]\n  [bt] (1) /usr/local/lib/python3.10/dist-packages/xgboost/lib/libxgboost.so(+0x60c6ce) [0x7ebdc8f726ce]\n  [bt] (2) /usr/local/lib/python3.10/dist-packages/xgboost/lib/libxgboost.so(+0x4b9c3f) [0x7ebdc8e1fc3f]\n  [bt] (3) /usr/local/lib/python3.10/dist-packages/xgboost/lib/libxgboost.so(+0x4cccd3) [0x7ebdc8e32cd3]\n  [bt] (4) /usr/local/lib/python3.10/dist-packages/xgboost/lib/libxgboost.so(+0x4c5268) [0x7ebdc8e2b268]\n  [bt] (5) /usr/local/lib/python3.10/dist-packages/xgboost/lib/libxgboost.so(XGBoosterUpdateOneIter+0x70) [0x7ebdc8ac7ef0]\n  [bt] (6) /lib/x86_64-linux-gnu/libffi.so.8(+0x7e2e) [0x7ebe31e94e2e]\n  [bt] (7) /lib/x86_64-linux-gnu/libffi.so.8(+0x4493) [0x7ebe31e91493]\n  [bt] (8) /usr/lib/python3.10/lib-dynload/_ctypes.cpython-310-x86_64-linux-gnu.so(+0xa3e9) [0x7ebe31eba3e9]\n\n\n\n--------------------------------------------------------------------------------\n41 fits failed with the following error:\nTraceback (most recent call last):\n  File \"/usr/local/lib/python3.10/dist-packages/sklearn/model_selection/_validation.py\", line 686, in _fit_and_score\n    estimator.fit(X_train, y_train, **fit_params)\n  File \"/usr/local/lib/python3.10/dist-packages/xgboost/core.py\", line 730, in inner_f\n    return func(**kwargs)\n  File \"/usr/local/lib/python3.10/dist-packages/xgboost/sklearn.py\", line 1090, in fit\n    self._Booster = train(\n  File \"/usr/local/lib/python3.10/dist-packages/xgboost/core.py\", line 730, in inner_f\n    return func(**kwargs)\n  File \"/usr/local/lib/python3.10/dist-packages/xgboost/training.py\", line 181, in train\n    bst.update(dtrain, i, obj)\n  File \"/usr/local/lib/python3.10/dist-packages/xgboost/core.py\", line 2050, in update\n    _check_call(\n  File \"/usr/local/lib/python3.10/dist-packages/xgboost/core.py\", line 282, in _check_call\n    raise XGBoostError(py_str(_LIB.XGBGetLastError()))\nxgboost.core.XGBoostError: [19:44:47] /workspace/src/objective/objective.cc:27: Unknown objective function: `squaredeerror`\nObjective candidate: rank:ndcg\nObjective candidate: rank:pairwise\nObjective candidate: rank:map\nObjective candidate: survival:aft\nObjective candidate: binary:hinge\nObjective candidate: multi:softmax\nObjective candidate: multi:softprob\nObjective candidate: reg:quantileerror\nObjective candidate: reg:squarederror\nObjective candidate: reg:squaredlogerror\nObjective candidate: reg:logistic\nObjective candidate: binary:logistic\nObjective candidate: binary:logitraw\nObjective candidate: reg:linear\nObjective candidate: reg:pseudohubererror\nObjective candidate: count:poisson\nObjective candidate: survival:cox\nObjective candidate: reg:gamma\nObjective candidate: reg:tweedie\nObjective candidate: reg:absoluteerror\n\nStack trace:\n  [bt] (0) /usr/local/lib/python3.10/dist-packages/xgboost/lib/libxgboost.so(+0x1ba24e) [0x7ebdc8b2024e]\n  [bt] (1) /usr/local/lib/python3.10/dist-packages/xgboost/lib/libxgboost.so(+0x60c6ce) [0x7ebdc8f726ce]\n  [bt] (2) /usr/local/lib/python3.10/dist-packages/xgboost/lib/libxgboost.so(+0x4b9c3f) [0x7ebdc8e1fc3f]\n  [bt] (3) /usr/local/lib/python3.10/dist-packages/xgboost/lib/libxgboost.so(+0x4cccd3) [0x7ebdc8e32cd3]\n  [bt] (4) /usr/local/lib/python3.10/dist-packages/xgboost/lib/libxgboost.so(+0x4c5268) [0x7ebdc8e2b268]\n  [bt] (5) /usr/local/lib/python3.10/dist-packages/xgboost/lib/libxgboost.so(XGBoosterUpdateOneIter+0x70) [0x7ebdc8ac7ef0]\n  [bt] (6) /lib/x86_64-linux-gnu/libffi.so.8(+0x7e2e) [0x7ebe31e94e2e]\n  [bt] (7) /lib/x86_64-linux-gnu/libffi.so.8(+0x4493) [0x7ebe31e91493]\n  [bt] (8) /usr/lib/python3.10/lib-dynload/_ctypes.cpython-310-x86_64-linux-gnu.so(+0xa3e9) [0x7ebe31eba3e9]\n\n\n\n--------------------------------------------------------------------------------\n42 fits failed with the following error:\nTraceback (most recent call last):\n  File \"/usr/local/lib/python3.10/dist-packages/sklearn/model_selection/_validation.py\", line 686, in _fit_and_score\n    estimator.fit(X_train, y_train, **fit_params)\n  File \"/usr/local/lib/python3.10/dist-packages/xgboost/core.py\", line 730, in inner_f\n    return func(**kwargs)\n  File \"/usr/local/lib/python3.10/dist-packages/xgboost/sklearn.py\", line 1090, in fit\n    self._Booster = train(\n  File \"/usr/local/lib/python3.10/dist-packages/xgboost/core.py\", line 730, in inner_f\n    return func(**kwargs)\n  File \"/usr/local/lib/python3.10/dist-packages/xgboost/training.py\", line 181, in train\n    bst.update(dtrain, i, obj)\n  File \"/usr/local/lib/python3.10/dist-packages/xgboost/core.py\", line 2050, in update\n    _check_call(\n  File \"/usr/local/lib/python3.10/dist-packages/xgboost/core.py\", line 282, in _check_call\n    raise XGBoostError(py_str(_LIB.XGBGetLastError()))\nxgboost.core.XGBoostError: [19:44:48] /workspace/src/objective/objective.cc:27: Unknown objective function: `squaredeerror`\nObjective candidate: rank:ndcg\nObjective candidate: rank:pairwise\nObjective candidate: rank:map\nObjective candidate: survival:aft\nObjective candidate: binary:hinge\nObjective candidate: multi:softmax\nObjective candidate: multi:softprob\nObjective candidate: reg:quantileerror\nObjective candidate: reg:squarederror\nObjective candidate: reg:squaredlogerror\nObjective candidate: reg:logistic\nObjective candidate: binary:logistic\nObjective candidate: binary:logitraw\nObjective candidate: reg:linear\nObjective candidate: reg:pseudohubererror\nObjective candidate: count:poisson\nObjective candidate: survival:cox\nObjective candidate: reg:gamma\nObjective candidate: reg:tweedie\nObjective candidate: reg:absoluteerror\n\nStack trace:\n  [bt] (0) /usr/local/lib/python3.10/dist-packages/xgboost/lib/libxgboost.so(+0x1ba24e) [0x7ebdc8b2024e]\n  [bt] (1) /usr/local/lib/python3.10/dist-packages/xgboost/lib/libxgboost.so(+0x60c6ce) [0x7ebdc8f726ce]\n  [bt] (2) /usr/local/lib/python3.10/dist-packages/xgboost/lib/libxgboost.so(+0x4b9c3f) [0x7ebdc8e1fc3f]\n  [bt] (3) /usr/local/lib/python3.10/dist-packages/xgboost/lib/libxgboost.so(+0x4cccd3) [0x7ebdc8e32cd3]\n  [bt] (4) /usr/local/lib/python3.10/dist-packages/xgboost/lib/libxgboost.so(+0x4c5268) [0x7ebdc8e2b268]\n  [bt] (5) /usr/local/lib/python3.10/dist-packages/xgboost/lib/libxgboost.so(XGBoosterUpdateOneIter+0x70) [0x7ebdc8ac7ef0]\n  [bt] (6) /lib/x86_64-linux-gnu/libffi.so.8(+0x7e2e) [0x7ebe31e94e2e]\n  [bt] (7) /lib/x86_64-linux-gnu/libffi.so.8(+0x4493) [0x7ebe31e91493]\n  [bt] (8) /usr/lib/python3.10/lib-dynload/_ctypes.cpython-310-x86_64-linux-gnu.so(+0xa3e9) [0x7ebe31eba3e9]\n\n\n\n--------------------------------------------------------------------------------\n41 fits failed with the following error:\nTraceback (most recent call last):\n  File \"/usr/local/lib/python3.10/dist-packages/sklearn/model_selection/_validation.py\", line 686, in _fit_and_score\n    estimator.fit(X_train, y_train, **fit_params)\n  File \"/usr/local/lib/python3.10/dist-packages/xgboost/core.py\", line 730, in inner_f\n    return func(**kwargs)\n  File \"/usr/local/lib/python3.10/dist-packages/xgboost/sklearn.py\", line 1090, in fit\n    self._Booster = train(\n  File \"/usr/local/lib/python3.10/dist-packages/xgboost/core.py\", line 730, in inner_f\n    return func(**kwargs)\n  File \"/usr/local/lib/python3.10/dist-packages/xgboost/training.py\", line 181, in train\n    bst.update(dtrain, i, obj)\n  File \"/usr/local/lib/python3.10/dist-packages/xgboost/core.py\", line 2050, in update\n    _check_call(\n  File \"/usr/local/lib/python3.10/dist-packages/xgboost/core.py\", line 282, in _check_call\n    raise XGBoostError(py_str(_LIB.XGBGetLastError()))\nxgboost.core.XGBoostError: [19:44:49] /workspace/src/objective/objective.cc:27: Unknown objective function: `squaredeerror`\nObjective candidate: rank:ndcg\nObjective candidate: rank:pairwise\nObjective candidate: rank:map\nObjective candidate: survival:aft\nObjective candidate: binary:hinge\nObjective candidate: multi:softmax\nObjective candidate: multi:softprob\nObjective candidate: reg:quantileerror\nObjective candidate: reg:squarederror\nObjective candidate: reg:squaredlogerror\nObjective candidate: reg:logistic\nObjective candidate: binary:logistic\nObjective candidate: binary:logitraw\nObjective candidate: reg:linear\nObjective candidate: reg:pseudohubererror\nObjective candidate: count:poisson\nObjective candidate: survival:cox\nObjective candidate: reg:gamma\nObjective candidate: reg:tweedie\nObjective candidate: reg:absoluteerror\n\nStack trace:\n  [bt] (0) /usr/local/lib/python3.10/dist-packages/xgboost/lib/libxgboost.so(+0x1ba24e) [0x7ebdc8b2024e]\n  [bt] (1) /usr/local/lib/python3.10/dist-packages/xgboost/lib/libxgboost.so(+0x60c6ce) [0x7ebdc8f726ce]\n  [bt] (2) /usr/local/lib/python3.10/dist-packages/xgboost/lib/libxgboost.so(+0x4b9c3f) [0x7ebdc8e1fc3f]\n  [bt] (3) /usr/local/lib/python3.10/dist-packages/xgboost/lib/libxgboost.so(+0x4cccd3) [0x7ebdc8e32cd3]\n  [bt] (4) /usr/local/lib/python3.10/dist-packages/xgboost/lib/libxgboost.so(+0x4c5268) [0x7ebdc8e2b268]\n  [bt] (5) /usr/local/lib/python3.10/dist-packages/xgboost/lib/libxgboost.so(XGBoosterUpdateOneIter+0x70) [0x7ebdc8ac7ef0]\n  [bt] (6) /lib/x86_64-linux-gnu/libffi.so.8(+0x7e2e) [0x7ebe31e94e2e]\n  [bt] (7) /lib/x86_64-linux-gnu/libffi.so.8(+0x4493) [0x7ebe31e91493]\n  [bt] (8) /usr/lib/python3.10/lib-dynload/_ctypes.cpython-310-x86_64-linux-gnu.so(+0xa3e9) [0x7ebe31eba3e9]\n\n\n\n--------------------------------------------------------------------------------\n32 fits failed with the following error:\nTraceback (most recent call last):\n  File \"/usr/local/lib/python3.10/dist-packages/sklearn/model_selection/_validation.py\", line 686, in _fit_and_score\n    estimator.fit(X_train, y_train, **fit_params)\n  File \"/usr/local/lib/python3.10/dist-packages/xgboost/core.py\", line 730, in inner_f\n    return func(**kwargs)\n  File \"/usr/local/lib/python3.10/dist-packages/xgboost/sklearn.py\", line 1090, in fit\n    self._Booster = train(\n  File \"/usr/local/lib/python3.10/dist-packages/xgboost/core.py\", line 730, in inner_f\n    return func(**kwargs)\n  File \"/usr/local/lib/python3.10/dist-packages/xgboost/training.py\", line 181, in train\n    bst.update(dtrain, i, obj)\n  File \"/usr/local/lib/python3.10/dist-packages/xgboost/core.py\", line 2050, in update\n    _check_call(\n  File \"/usr/local/lib/python3.10/dist-packages/xgboost/core.py\", line 282, in _check_call\n    raise XGBoostError(py_str(_LIB.XGBGetLastError()))\nxgboost.core.XGBoostError: [19:44:50] /workspace/src/objective/objective.cc:27: Unknown objective function: `squaredeerror`\nObjective candidate: rank:ndcg\nObjective candidate: rank:pairwise\nObjective candidate: rank:map\nObjective candidate: survival:aft\nObjective candidate: binary:hinge\nObjective candidate: multi:softmax\nObjective candidate: multi:softprob\nObjective candidate: reg:quantileerror\nObjective candidate: reg:squarederror\nObjective candidate: reg:squaredlogerror\nObjective candidate: reg:logistic\nObjective candidate: binary:logistic\nObjective candidate: binary:logitraw\nObjective candidate: reg:linear\nObjective candidate: reg:pseudohubererror\nObjective candidate: count:poisson\nObjective candidate: survival:cox\nObjective candidate: reg:gamma\nObjective candidate: reg:tweedie\nObjective candidate: reg:absoluteerror\n\nStack trace:\n  [bt] (0) /usr/local/lib/python3.10/dist-packages/xgboost/lib/libxgboost.so(+0x1ba24e) [0x7ebdc8b2024e]\n  [bt] (1) /usr/local/lib/python3.10/dist-packages/xgboost/lib/libxgboost.so(+0x60c6ce) [0x7ebdc8f726ce]\n  [bt] (2) /usr/local/lib/python3.10/dist-packages/xgboost/lib/libxgboost.so(+0x4b9c3f) [0x7ebdc8e1fc3f]\n  [bt] (3) /usr/local/lib/python3.10/dist-packages/xgboost/lib/libxgboost.so(+0x4cccd3) [0x7ebdc8e32cd3]\n  [bt] (4) /usr/local/lib/python3.10/dist-packages/xgboost/lib/libxgboost.so(+0x4c5268) [0x7ebdc8e2b268]\n  [bt] (5) /usr/local/lib/python3.10/dist-packages/xgboost/lib/libxgboost.so(XGBoosterUpdateOneIter+0x70) [0x7ebdc8ac7ef0]\n  [bt] (6) /lib/x86_64-linux-gnu/libffi.so.8(+0x7e2e) [0x7ebe31e94e2e]\n  [bt] (7) /lib/x86_64-linux-gnu/libffi.so.8(+0x4493) [0x7ebe31e91493]\n  [bt] (8) /usr/lib/python3.10/lib-dynload/_ctypes.cpython-310-x86_64-linux-gnu.so(+0xa3e9) [0x7ebe31eba3e9]\n\n\n\n--------------------------------------------------------------------------------\n11 fits failed with the following error:\nTraceback (most recent call last):\n  File \"/usr/local/lib/python3.10/dist-packages/sklearn/model_selection/_validation.py\", line 686, in _fit_and_score\n    estimator.fit(X_train, y_train, **fit_params)\n  File \"/usr/local/lib/python3.10/dist-packages/xgboost/core.py\", line 730, in inner_f\n    return func(**kwargs)\n  File \"/usr/local/lib/python3.10/dist-packages/xgboost/sklearn.py\", line 1090, in fit\n    self._Booster = train(\n  File \"/usr/local/lib/python3.10/dist-packages/xgboost/core.py\", line 730, in inner_f\n    return func(**kwargs)\n  File \"/usr/local/lib/python3.10/dist-packages/xgboost/training.py\", line 181, in train\n    bst.update(dtrain, i, obj)\n  File \"/usr/local/lib/python3.10/dist-packages/xgboost/core.py\", line 2050, in update\n    _check_call(\n  File \"/usr/local/lib/python3.10/dist-packages/xgboost/core.py\", line 282, in _check_call\n    raise XGBoostError(py_str(_LIB.XGBGetLastError()))\nxgboost.core.XGBoostError: [19:44:51] /workspace/src/objective/objective.cc:27: Unknown objective function: `squaredeerror`\nObjective candidate: rank:ndcg\nObjective candidate: rank:pairwise\nObjective candidate: rank:map\nObjective candidate: survival:aft\nObjective candidate: binary:hinge\nObjective candidate: multi:softmax\nObjective candidate: multi:softprob\nObjective candidate: reg:quantileerror\nObjective candidate: reg:squarederror\nObjective candidate: reg:squaredlogerror\nObjective candidate: reg:logistic\nObjective candidate: binary:logistic\nObjective candidate: binary:logitraw\nObjective candidate: reg:linear\nObjective candidate: reg:pseudohubererror\nObjective candidate: count:poisson\nObjective candidate: survival:cox\nObjective candidate: reg:gamma\nObjective candidate: reg:tweedie\nObjective candidate: reg:absoluteerror\n\nStack trace:\n  [bt] (0) /usr/local/lib/python3.10/dist-packages/xgboost/lib/libxgboost.so(+0x1ba24e) [0x7ebdc8b2024e]\n  [bt] (1) /usr/local/lib/python3.10/dist-packages/xgboost/lib/libxgboost.so(+0x60c6ce) [0x7ebdc8f726ce]\n  [bt] (2) /usr/local/lib/python3.10/dist-packages/xgboost/lib/libxgboost.so(+0x4b9c3f) [0x7ebdc8e1fc3f]\n  [bt] (3) /usr/local/lib/python3.10/dist-packages/xgboost/lib/libxgboost.so(+0x4cccd3) [0x7ebdc8e32cd3]\n  [bt] (4) /usr/local/lib/python3.10/dist-packages/xgboost/lib/libxgboost.so(+0x4c5268) [0x7ebdc8e2b268]\n  [bt] (5) /usr/local/lib/python3.10/dist-packages/xgboost/lib/libxgboost.so(XGBoosterUpdateOneIter+0x70) [0x7ebdc8ac7ef0]\n  [bt] (6) /lib/x86_64-linux-gnu/libffi.so.8(+0x7e2e) [0x7ebe31e94e2e]\n  [bt] (7) /lib/x86_64-linux-gnu/libffi.so.8(+0x4493) [0x7ebe31e91493]\n  [bt] (8) /usr/lib/python3.10/lib-dynload/_ctypes.cpython-310-x86_64-linux-gnu.so(+0xa3e9) [0x7ebe31eba3e9]\n\n\n\n--------------------------------------------------------------------------------\n11 fits failed with the following error:\nTraceback (most recent call last):\n  File \"/usr/local/lib/python3.10/dist-packages/sklearn/model_selection/_validation.py\", line 686, in _fit_and_score\n    estimator.fit(X_train, y_train, **fit_params)\n  File \"/usr/local/lib/python3.10/dist-packages/xgboost/core.py\", line 730, in inner_f\n    return func(**kwargs)\n  File \"/usr/local/lib/python3.10/dist-packages/xgboost/sklearn.py\", line 1090, in fit\n    self._Booster = train(\n  File \"/usr/local/lib/python3.10/dist-packages/xgboost/core.py\", line 730, in inner_f\n    return func(**kwargs)\n  File \"/usr/local/lib/python3.10/dist-packages/xgboost/training.py\", line 181, in train\n    bst.update(dtrain, i, obj)\n  File \"/usr/local/lib/python3.10/dist-packages/xgboost/core.py\", line 2050, in update\n    _check_call(\n  File \"/usr/local/lib/python3.10/dist-packages/xgboost/core.py\", line 282, in _check_call\n    raise XGBoostError(py_str(_LIB.XGBGetLastError()))\nxgboost.core.XGBoostError: [19:44:52] /workspace/src/objective/objective.cc:27: Unknown objective function: `squaredeerror`\nObjective candidate: rank:ndcg\nObjective candidate: rank:pairwise\nObjective candidate: rank:map\nObjective candidate: survival:aft\nObjective candidate: binary:hinge\nObjective candidate: multi:softmax\nObjective candidate: multi:softprob\nObjective candidate: reg:quantileerror\nObjective candidate: reg:squarederror\nObjective candidate: reg:squaredlogerror\nObjective candidate: reg:logistic\nObjective candidate: binary:logistic\nObjective candidate: binary:logitraw\nObjective candidate: reg:linear\nObjective candidate: reg:pseudohubererror\nObjective candidate: count:poisson\nObjective candidate: survival:cox\nObjective candidate: reg:gamma\nObjective candidate: reg:tweedie\nObjective candidate: reg:absoluteerror\n\nStack trace:\n  [bt] (0) /usr/local/lib/python3.10/dist-packages/xgboost/lib/libxgboost.so(+0x1ba24e) [0x7ebdc8b2024e]\n  [bt] (1) /usr/local/lib/python3.10/dist-packages/xgboost/lib/libxgboost.so(+0x60c6ce) [0x7ebdc8f726ce]\n  [bt] (2) /usr/local/lib/python3.10/dist-packages/xgboost/lib/libxgboost.so(+0x4b9c3f) [0x7ebdc8e1fc3f]\n  [bt] (3) /usr/local/lib/python3.10/dist-packages/xgboost/lib/libxgboost.so(+0x4cccd3) [0x7ebdc8e32cd3]\n  [bt] (4) /usr/local/lib/python3.10/dist-packages/xgboost/lib/libxgboost.so(+0x4c5268) [0x7ebdc8e2b268]\n  [bt] (5) /usr/local/lib/python3.10/dist-packages/xgboost/lib/libxgboost.so(XGBoosterUpdateOneIter+0x70) [0x7ebdc8ac7ef0]\n  [bt] (6) /lib/x86_64-linux-gnu/libffi.so.8(+0x7e2e) [0x7ebe31e94e2e]\n  [bt] (7) /lib/x86_64-linux-gnu/libffi.so.8(+0x4493) [0x7ebe31e91493]\n  [bt] (8) /usr/lib/python3.10/lib-dynload/_ctypes.cpython-310-x86_64-linux-gnu.so(+0xa3e9) [0x7ebe31eba3e9]\n\n\n\n--------------------------------------------------------------------------------\n32 fits failed with the following error:\nTraceback (most recent call last):\n  File \"/usr/local/lib/python3.10/dist-packages/sklearn/model_selection/_validation.py\", line 686, in _fit_and_score\n    estimator.fit(X_train, y_train, **fit_params)\n  File \"/usr/local/lib/python3.10/dist-packages/xgboost/core.py\", line 730, in inner_f\n    return func(**kwargs)\n  File \"/usr/local/lib/python3.10/dist-packages/xgboost/sklearn.py\", line 1090, in fit\n    self._Booster = train(\n  File \"/usr/local/lib/python3.10/dist-packages/xgboost/core.py\", line 730, in inner_f\n    return func(**kwargs)\n  File \"/usr/local/lib/python3.10/dist-packages/xgboost/training.py\", line 181, in train\n    bst.update(dtrain, i, obj)\n  File \"/usr/local/lib/python3.10/dist-packages/xgboost/core.py\", line 2050, in update\n    _check_call(\n  File \"/usr/local/lib/python3.10/dist-packages/xgboost/core.py\", line 282, in _check_call\n    raise XGBoostError(py_str(_LIB.XGBGetLastError()))\nxgboost.core.XGBoostError: [19:44:53] /workspace/src/objective/objective.cc:27: Unknown objective function: `squaredeerror`\nObjective candidate: rank:ndcg\nObjective candidate: rank:pairwise\nObjective candidate: rank:map\nObjective candidate: survival:aft\nObjective candidate: binary:hinge\nObjective candidate: multi:softmax\nObjective candidate: multi:softprob\nObjective candidate: reg:quantileerror\nObjective candidate: reg:squarederror\nObjective candidate: reg:squaredlogerror\nObjective candidate: reg:logistic\nObjective candidate: binary:logistic\nObjective candidate: binary:logitraw\nObjective candidate: reg:linear\nObjective candidate: reg:pseudohubererror\nObjective candidate: count:poisson\nObjective candidate: survival:cox\nObjective candidate: reg:gamma\nObjective candidate: reg:tweedie\nObjective candidate: reg:absoluteerror\n\nStack trace:\n  [bt] (0) /usr/local/lib/python3.10/dist-packages/xgboost/lib/libxgboost.so(+0x1ba24e) [0x7ebdc8b2024e]\n  [bt] (1) /usr/local/lib/python3.10/dist-packages/xgboost/lib/libxgboost.so(+0x60c6ce) [0x7ebdc8f726ce]\n  [bt] (2) /usr/local/lib/python3.10/dist-packages/xgboost/lib/libxgboost.so(+0x4b9c3f) [0x7ebdc8e1fc3f]\n  [bt] (3) /usr/local/lib/python3.10/dist-packages/xgboost/lib/libxgboost.so(+0x4cccd3) [0x7ebdc8e32cd3]\n  [bt] (4) /usr/local/lib/python3.10/dist-packages/xgboost/lib/libxgboost.so(+0x4c5268) [0x7ebdc8e2b268]\n  [bt] (5) /usr/local/lib/python3.10/dist-packages/xgboost/lib/libxgboost.so(XGBoosterUpdateOneIter+0x70) [0x7ebdc8ac7ef0]\n  [bt] (6) /lib/x86_64-linux-gnu/libffi.so.8(+0x7e2e) [0x7ebe31e94e2e]\n  [bt] (7) /lib/x86_64-linux-gnu/libffi.so.8(+0x4493) [0x7ebe31e91493]\n  [bt] (8) /usr/lib/python3.10/lib-dynload/_ctypes.cpython-310-x86_64-linux-gnu.so(+0xa3e9) [0x7ebe31eba3e9]\n\n\n\n--------------------------------------------------------------------------------\n42 fits failed with the following error:\nTraceback (most recent call last):\n  File \"/usr/local/lib/python3.10/dist-packages/sklearn/model_selection/_validation.py\", line 686, in _fit_and_score\n    estimator.fit(X_train, y_train, **fit_params)\n  File \"/usr/local/lib/python3.10/dist-packages/xgboost/core.py\", line 730, in inner_f\n    return func(**kwargs)\n  File \"/usr/local/lib/python3.10/dist-packages/xgboost/sklearn.py\", line 1090, in fit\n    self._Booster = train(\n  File \"/usr/local/lib/python3.10/dist-packages/xgboost/core.py\", line 730, in inner_f\n    return func(**kwargs)\n  File \"/usr/local/lib/python3.10/dist-packages/xgboost/training.py\", line 181, in train\n    bst.update(dtrain, i, obj)\n  File \"/usr/local/lib/python3.10/dist-packages/xgboost/core.py\", line 2050, in update\n    _check_call(\n  File \"/usr/local/lib/python3.10/dist-packages/xgboost/core.py\", line 282, in _check_call\n    raise XGBoostError(py_str(_LIB.XGBGetLastError()))\nxgboost.core.XGBoostError: [19:44:54] /workspace/src/objective/objective.cc:27: Unknown objective function: `squaredeerror`\nObjective candidate: rank:ndcg\nObjective candidate: rank:pairwise\nObjective candidate: rank:map\nObjective candidate: survival:aft\nObjective candidate: binary:hinge\nObjective candidate: multi:softmax\nObjective candidate: multi:softprob\nObjective candidate: reg:quantileerror\nObjective candidate: reg:squarederror\nObjective candidate: reg:squaredlogerror\nObjective candidate: reg:logistic\nObjective candidate: binary:logistic\nObjective candidate: binary:logitraw\nObjective candidate: reg:linear\nObjective candidate: reg:pseudohubererror\nObjective candidate: count:poisson\nObjective candidate: survival:cox\nObjective candidate: reg:gamma\nObjective candidate: reg:tweedie\nObjective candidate: reg:absoluteerror\n\nStack trace:\n  [bt] (0) /usr/local/lib/python3.10/dist-packages/xgboost/lib/libxgboost.so(+0x1ba24e) [0x7ebdc8b2024e]\n  [bt] (1) /usr/local/lib/python3.10/dist-packages/xgboost/lib/libxgboost.so(+0x60c6ce) [0x7ebdc8f726ce]\n  [bt] (2) /usr/local/lib/python3.10/dist-packages/xgboost/lib/libxgboost.so(+0x4b9c3f) [0x7ebdc8e1fc3f]\n  [bt] (3) /usr/local/lib/python3.10/dist-packages/xgboost/lib/libxgboost.so(+0x4cccd3) [0x7ebdc8e32cd3]\n  [bt] (4) /usr/local/lib/python3.10/dist-packages/xgboost/lib/libxgboost.so(+0x4c5268) [0x7ebdc8e2b268]\n  [bt] (5) /usr/local/lib/python3.10/dist-packages/xgboost/lib/libxgboost.so(XGBoosterUpdateOneIter+0x70) [0x7ebdc8ac7ef0]\n  [bt] (6) /lib/x86_64-linux-gnu/libffi.so.8(+0x7e2e) [0x7ebe31e94e2e]\n  [bt] (7) /lib/x86_64-linux-gnu/libffi.so.8(+0x4493) [0x7ebe31e91493]\n  [bt] (8) /usr/lib/python3.10/lib-dynload/_ctypes.cpython-310-x86_64-linux-gnu.so(+0xa3e9) [0x7ebe31eba3e9]\n\n\n\n--------------------------------------------------------------------------------\n41 fits failed with the following error:\nTraceback (most recent call last):\n  File \"/usr/local/lib/python3.10/dist-packages/sklearn/model_selection/_validation.py\", line 686, in _fit_and_score\n    estimator.fit(X_train, y_train, **fit_params)\n  File \"/usr/local/lib/python3.10/dist-packages/xgboost/core.py\", line 730, in inner_f\n    return func(**kwargs)\n  File \"/usr/local/lib/python3.10/dist-packages/xgboost/sklearn.py\", line 1090, in fit\n    self._Booster = train(\n  File \"/usr/local/lib/python3.10/dist-packages/xgboost/core.py\", line 730, in inner_f\n    return func(**kwargs)\n  File \"/usr/local/lib/python3.10/dist-packages/xgboost/training.py\", line 181, in train\n    bst.update(dtrain, i, obj)\n  File \"/usr/local/lib/python3.10/dist-packages/xgboost/core.py\", line 2050, in update\n    _check_call(\n  File \"/usr/local/lib/python3.10/dist-packages/xgboost/core.py\", line 282, in _check_call\n    raise XGBoostError(py_str(_LIB.XGBGetLastError()))\nxgboost.core.XGBoostError: [19:44:55] /workspace/src/objective/objective.cc:27: Unknown objective function: `squaredeerror`\nObjective candidate: rank:ndcg\nObjective candidate: rank:pairwise\nObjective candidate: rank:map\nObjective candidate: survival:aft\nObjective candidate: binary:hinge\nObjective candidate: multi:softmax\nObjective candidate: multi:softprob\nObjective candidate: reg:quantileerror\nObjective candidate: reg:squarederror\nObjective candidate: reg:squaredlogerror\nObjective candidate: reg:logistic\nObjective candidate: binary:logistic\nObjective candidate: binary:logitraw\nObjective candidate: reg:linear\nObjective candidate: reg:pseudohubererror\nObjective candidate: count:poisson\nObjective candidate: survival:cox\nObjective candidate: reg:gamma\nObjective candidate: reg:tweedie\nObjective candidate: reg:absoluteerror\n\nStack trace:\n  [bt] (0) /usr/local/lib/python3.10/dist-packages/xgboost/lib/libxgboost.so(+0x1ba24e) [0x7ebdc8b2024e]\n  [bt] (1) /usr/local/lib/python3.10/dist-packages/xgboost/lib/libxgboost.so(+0x60c6ce) [0x7ebdc8f726ce]\n  [bt] (2) /usr/local/lib/python3.10/dist-packages/xgboost/lib/libxgboost.so(+0x4b9c3f) [0x7ebdc8e1fc3f]\n  [bt] (3) /usr/local/lib/python3.10/dist-packages/xgboost/lib/libxgboost.so(+0x4cccd3) [0x7ebdc8e32cd3]\n  [bt] (4) /usr/local/lib/python3.10/dist-packages/xgboost/lib/libxgboost.so(+0x4c5268) [0x7ebdc8e2b268]\n  [bt] (5) /usr/local/lib/python3.10/dist-packages/xgboost/lib/libxgboost.so(XGBoosterUpdateOneIter+0x70) [0x7ebdc8ac7ef0]\n  [bt] (6) /lib/x86_64-linux-gnu/libffi.so.8(+0x7e2e) [0x7ebe31e94e2e]\n  [bt] (7) /lib/x86_64-linux-gnu/libffi.so.8(+0x4493) [0x7ebe31e91493]\n  [bt] (8) /usr/lib/python3.10/lib-dynload/_ctypes.cpython-310-x86_64-linux-gnu.so(+0xa3e9) [0x7ebe31eba3e9]\n\n\n\n--------------------------------------------------------------------------------\n42 fits failed with the following error:\nTraceback (most recent call last):\n  File \"/usr/local/lib/python3.10/dist-packages/sklearn/model_selection/_validation.py\", line 686, in _fit_and_score\n    estimator.fit(X_train, y_train, **fit_params)\n  File \"/usr/local/lib/python3.10/dist-packages/xgboost/core.py\", line 730, in inner_f\n    return func(**kwargs)\n  File \"/usr/local/lib/python3.10/dist-packages/xgboost/sklearn.py\", line 1090, in fit\n    self._Booster = train(\n  File \"/usr/local/lib/python3.10/dist-packages/xgboost/core.py\", line 730, in inner_f\n    return func(**kwargs)\n  File \"/usr/local/lib/python3.10/dist-packages/xgboost/training.py\", line 181, in train\n    bst.update(dtrain, i, obj)\n  File \"/usr/local/lib/python3.10/dist-packages/xgboost/core.py\", line 2050, in update\n    _check_call(\n  File \"/usr/local/lib/python3.10/dist-packages/xgboost/core.py\", line 282, in _check_call\n    raise XGBoostError(py_str(_LIB.XGBGetLastError()))\nxgboost.core.XGBoostError: [19:44:56] /workspace/src/objective/objective.cc:27: Unknown objective function: `squaredeerror`\nObjective candidate: rank:ndcg\nObjective candidate: rank:pairwise\nObjective candidate: rank:map\nObjective candidate: survival:aft\nObjective candidate: binary:hinge\nObjective candidate: multi:softmax\nObjective candidate: multi:softprob\nObjective candidate: reg:quantileerror\nObjective candidate: reg:squarederror\nObjective candidate: reg:squaredlogerror\nObjective candidate: reg:logistic\nObjective candidate: binary:logistic\nObjective candidate: binary:logitraw\nObjective candidate: reg:linear\nObjective candidate: reg:pseudohubererror\nObjective candidate: count:poisson\nObjective candidate: survival:cox\nObjective candidate: reg:gamma\nObjective candidate: reg:tweedie\nObjective candidate: reg:absoluteerror\n\nStack trace:\n  [bt] (0) /usr/local/lib/python3.10/dist-packages/xgboost/lib/libxgboost.so(+0x1ba24e) [0x7ebdc8b2024e]\n  [bt] (1) /usr/local/lib/python3.10/dist-packages/xgboost/lib/libxgboost.so(+0x60c6ce) [0x7ebdc8f726ce]\n  [bt] (2) /usr/local/lib/python3.10/dist-packages/xgboost/lib/libxgboost.so(+0x4b9c3f) [0x7ebdc8e1fc3f]\n  [bt] (3) /usr/local/lib/python3.10/dist-packages/xgboost/lib/libxgboost.so(+0x4cccd3) [0x7ebdc8e32cd3]\n  [bt] (4) /usr/local/lib/python3.10/dist-packages/xgboost/lib/libxgboost.so(+0x4c5268) [0x7ebdc8e2b268]\n  [bt] (5) /usr/local/lib/python3.10/dist-packages/xgboost/lib/libxgboost.so(XGBoosterUpdateOneIter+0x70) [0x7ebdc8ac7ef0]\n  [bt] (6) /lib/x86_64-linux-gnu/libffi.so.8(+0x7e2e) [0x7ebe31e94e2e]\n  [bt] (7) /lib/x86_64-linux-gnu/libffi.so.8(+0x4493) [0x7ebe31e91493]\n  [bt] (8) /usr/lib/python3.10/lib-dynload/_ctypes.cpython-310-x86_64-linux-gnu.so(+0xa3e9) [0x7ebe31eba3e9]\n\n\n\n--------------------------------------------------------------------------------\n41 fits failed with the following error:\nTraceback (most recent call last):\n  File \"/usr/local/lib/python3.10/dist-packages/sklearn/model_selection/_validation.py\", line 686, in _fit_and_score\n    estimator.fit(X_train, y_train, **fit_params)\n  File \"/usr/local/lib/python3.10/dist-packages/xgboost/core.py\", line 730, in inner_f\n    return func(**kwargs)\n  File \"/usr/local/lib/python3.10/dist-packages/xgboost/sklearn.py\", line 1090, in fit\n    self._Booster = train(\n  File \"/usr/local/lib/python3.10/dist-packages/xgboost/core.py\", line 730, in inner_f\n    return func(**kwargs)\n  File \"/usr/local/lib/python3.10/dist-packages/xgboost/training.py\", line 181, in train\n    bst.update(dtrain, i, obj)\n  File \"/usr/local/lib/python3.10/dist-packages/xgboost/core.py\", line 2050, in update\n    _check_call(\n  File \"/usr/local/lib/python3.10/dist-packages/xgboost/core.py\", line 282, in _check_call\n    raise XGBoostError(py_str(_LIB.XGBGetLastError()))\nxgboost.core.XGBoostError: [19:44:57] /workspace/src/objective/objective.cc:27: Unknown objective function: `squaredeerror`\nObjective candidate: rank:ndcg\nObjective candidate: rank:pairwise\nObjective candidate: rank:map\nObjective candidate: survival:aft\nObjective candidate: binary:hinge\nObjective candidate: multi:softmax\nObjective candidate: multi:softprob\nObjective candidate: reg:quantileerror\nObjective candidate: reg:squarederror\nObjective candidate: reg:squaredlogerror\nObjective candidate: reg:logistic\nObjective candidate: binary:logistic\nObjective candidate: binary:logitraw\nObjective candidate: reg:linear\nObjective candidate: reg:pseudohubererror\nObjective candidate: count:poisson\nObjective candidate: survival:cox\nObjective candidate: reg:gamma\nObjective candidate: reg:tweedie\nObjective candidate: reg:absoluteerror\n\nStack trace:\n  [bt] (0) /usr/local/lib/python3.10/dist-packages/xgboost/lib/libxgboost.so(+0x1ba24e) [0x7ebdc8b2024e]\n  [bt] (1) /usr/local/lib/python3.10/dist-packages/xgboost/lib/libxgboost.so(+0x60c6ce) [0x7ebdc8f726ce]\n  [bt] (2) /usr/local/lib/python3.10/dist-packages/xgboost/lib/libxgboost.so(+0x4b9c3f) [0x7ebdc8e1fc3f]\n  [bt] (3) /usr/local/lib/python3.10/dist-packages/xgboost/lib/libxgboost.so(+0x4cccd3) [0x7ebdc8e32cd3]\n  [bt] (4) /usr/local/lib/python3.10/dist-packages/xgboost/lib/libxgboost.so(+0x4c5268) [0x7ebdc8e2b268]\n  [bt] (5) /usr/local/lib/python3.10/dist-packages/xgboost/lib/libxgboost.so(XGBoosterUpdateOneIter+0x70) [0x7ebdc8ac7ef0]\n  [bt] (6) /lib/x86_64-linux-gnu/libffi.so.8(+0x7e2e) [0x7ebe31e94e2e]\n  [bt] (7) /lib/x86_64-linux-gnu/libffi.so.8(+0x4493) [0x7ebe31e91493]\n  [bt] (8) /usr/lib/python3.10/lib-dynload/_ctypes.cpython-310-x86_64-linux-gnu.so(+0xa3e9) [0x7ebe31eba3e9]\n\n\n\n--------------------------------------------------------------------------------\n41 fits failed with the following error:\nTraceback (most recent call last):\n  File \"/usr/local/lib/python3.10/dist-packages/sklearn/model_selection/_validation.py\", line 686, in _fit_and_score\n    estimator.fit(X_train, y_train, **fit_params)\n  File \"/usr/local/lib/python3.10/dist-packages/xgboost/core.py\", line 730, in inner_f\n    return func(**kwargs)\n  File \"/usr/local/lib/python3.10/dist-packages/xgboost/sklearn.py\", line 1090, in fit\n    self._Booster = train(\n  File \"/usr/local/lib/python3.10/dist-packages/xgboost/core.py\", line 730, in inner_f\n    return func(**kwargs)\n  File \"/usr/local/lib/python3.10/dist-packages/xgboost/training.py\", line 181, in train\n    bst.update(dtrain, i, obj)\n  File \"/usr/local/lib/python3.10/dist-packages/xgboost/core.py\", line 2050, in update\n    _check_call(\n  File \"/usr/local/lib/python3.10/dist-packages/xgboost/core.py\", line 282, in _check_call\n    raise XGBoostError(py_str(_LIB.XGBGetLastError()))\nxgboost.core.XGBoostError: [19:44:58] /workspace/src/objective/objective.cc:27: Unknown objective function: `squaredeerror`\nObjective candidate: rank:ndcg\nObjective candidate: rank:pairwise\nObjective candidate: rank:map\nObjective candidate: survival:aft\nObjective candidate: binary:hinge\nObjective candidate: multi:softmax\nObjective candidate: multi:softprob\nObjective candidate: reg:quantileerror\nObjective candidate: reg:squarederror\nObjective candidate: reg:squaredlogerror\nObjective candidate: reg:logistic\nObjective candidate: binary:logistic\nObjective candidate: binary:logitraw\nObjective candidate: reg:linear\nObjective candidate: reg:pseudohubererror\nObjective candidate: count:poisson\nObjective candidate: survival:cox\nObjective candidate: reg:gamma\nObjective candidate: reg:tweedie\nObjective candidate: reg:absoluteerror\n\nStack trace:\n  [bt] (0) /usr/local/lib/python3.10/dist-packages/xgboost/lib/libxgboost.so(+0x1ba24e) [0x7ebdc8b2024e]\n  [bt] (1) /usr/local/lib/python3.10/dist-packages/xgboost/lib/libxgboost.so(+0x60c6ce) [0x7ebdc8f726ce]\n  [bt] (2) /usr/local/lib/python3.10/dist-packages/xgboost/lib/libxgboost.so(+0x4b9c3f) [0x7ebdc8e1fc3f]\n  [bt] (3) /usr/local/lib/python3.10/dist-packages/xgboost/lib/libxgboost.so(+0x4cccd3) [0x7ebdc8e32cd3]\n  [bt] (4) /usr/local/lib/python3.10/dist-packages/xgboost/lib/libxgboost.so(+0x4c5268) [0x7ebdc8e2b268]\n  [bt] (5) /usr/local/lib/python3.10/dist-packages/xgboost/lib/libxgboost.so(XGBoosterUpdateOneIter+0x70) [0x7ebdc8ac7ef0]\n  [bt] (6) /lib/x86_64-linux-gnu/libffi.so.8(+0x7e2e) [0x7ebe31e94e2e]\n  [bt] (7) /lib/x86_64-linux-gnu/libffi.so.8(+0x4493) [0x7ebe31e91493]\n  [bt] (8) /usr/lib/python3.10/lib-dynload/_ctypes.cpython-310-x86_64-linux-gnu.so(+0xa3e9) [0x7ebe31eba3e9]\n\n\n\n--------------------------------------------------------------------------------\n27 fits failed with the following error:\nTraceback (most recent call last):\n  File \"/usr/local/lib/python3.10/dist-packages/sklearn/model_selection/_validation.py\", line 686, in _fit_and_score\n    estimator.fit(X_train, y_train, **fit_params)\n  File \"/usr/local/lib/python3.10/dist-packages/xgboost/core.py\", line 730, in inner_f\n    return func(**kwargs)\n  File \"/usr/local/lib/python3.10/dist-packages/xgboost/sklearn.py\", line 1090, in fit\n    self._Booster = train(\n  File \"/usr/local/lib/python3.10/dist-packages/xgboost/core.py\", line 730, in inner_f\n    return func(**kwargs)\n  File \"/usr/local/lib/python3.10/dist-packages/xgboost/training.py\", line 181, in train\n    bst.update(dtrain, i, obj)\n  File \"/usr/local/lib/python3.10/dist-packages/xgboost/core.py\", line 2050, in update\n    _check_call(\n  File \"/usr/local/lib/python3.10/dist-packages/xgboost/core.py\", line 282, in _check_call\n    raise XGBoostError(py_str(_LIB.XGBGetLastError()))\nxgboost.core.XGBoostError: [19:44:59] /workspace/src/objective/objective.cc:27: Unknown objective function: `squaredeerror`\nObjective candidate: rank:ndcg\nObjective candidate: rank:pairwise\nObjective candidate: rank:map\nObjective candidate: survival:aft\nObjective candidate: binary:hinge\nObjective candidate: multi:softmax\nObjective candidate: multi:softprob\nObjective candidate: reg:quantileerror\nObjective candidate: reg:squarederror\nObjective candidate: reg:squaredlogerror\nObjective candidate: reg:logistic\nObjective candidate: binary:logistic\nObjective candidate: binary:logitraw\nObjective candidate: reg:linear\nObjective candidate: reg:pseudohubererror\nObjective candidate: count:poisson\nObjective candidate: survival:cox\nObjective candidate: reg:gamma\nObjective candidate: reg:tweedie\nObjective candidate: reg:absoluteerror\n\nStack trace:\n  [bt] (0) /usr/local/lib/python3.10/dist-packages/xgboost/lib/libxgboost.so(+0x1ba24e) [0x7ebdc8b2024e]\n  [bt] (1) /usr/local/lib/python3.10/dist-packages/xgboost/lib/libxgboost.so(+0x60c6ce) [0x7ebdc8f726ce]\n  [bt] (2) /usr/local/lib/python3.10/dist-packages/xgboost/lib/libxgboost.so(+0x4b9c3f) [0x7ebdc8e1fc3f]\n  [bt] (3) /usr/local/lib/python3.10/dist-packages/xgboost/lib/libxgboost.so(+0x4cccd3) [0x7ebdc8e32cd3]\n  [bt] (4) /usr/local/lib/python3.10/dist-packages/xgboost/lib/libxgboost.so(+0x4c5268) [0x7ebdc8e2b268]\n  [bt] (5) /usr/local/lib/python3.10/dist-packages/xgboost/lib/libxgboost.so(XGBoosterUpdateOneIter+0x70) [0x7ebdc8ac7ef0]\n  [bt] (6) /lib/x86_64-linux-gnu/libffi.so.8(+0x7e2e) [0x7ebe31e94e2e]\n  [bt] (7) /lib/x86_64-linux-gnu/libffi.so.8(+0x4493) [0x7ebe31e91493]\n  [bt] (8) /usr/lib/python3.10/lib-dynload/_ctypes.cpython-310-x86_64-linux-gnu.so(+0xa3e9) [0x7ebe31eba3e9]\n\n\n",
          "traceback": [
            "\u001b[0;31m---------------------------------------------------------------------------\u001b[0m",
            "\u001b[0;31mValueError\u001b[0m                                Traceback (most recent call last)",
            "\u001b[0;32m<ipython-input-43-da7760d89bb8>\u001b[0m in \u001b[0;36m<cell line: 1>\u001b[0;34m()\u001b[0m\n\u001b[0;32m----> 1\u001b[0;31m \u001b[0mxgbGridModel\u001b[0m \u001b[0;34m=\u001b[0m \u001b[0mxgbGrid\u001b[0m\u001b[0;34m.\u001b[0m\u001b[0mfit\u001b[0m\u001b[0;34m(\u001b[0m\u001b[0mX_train\u001b[0m\u001b[0;34m,\u001b[0m \u001b[0my_train\u001b[0m\u001b[0;34m)\u001b[0m\u001b[0;34m\u001b[0m\u001b[0;34m\u001b[0m\u001b[0m\n\u001b[0m",
            "\u001b[0;32m/usr/local/lib/python3.10/dist-packages/sklearn/model_selection/_search.py\u001b[0m in \u001b[0;36mfit\u001b[0;34m(self, X, y, groups, **fit_params)\u001b[0m\n\u001b[1;32m    872\u001b[0m                 \u001b[0;32mreturn\u001b[0m \u001b[0mresults\u001b[0m\u001b[0;34m\u001b[0m\u001b[0;34m\u001b[0m\u001b[0m\n\u001b[1;32m    873\u001b[0m \u001b[0;34m\u001b[0m\u001b[0m\n\u001b[0;32m--> 874\u001b[0;31m             \u001b[0mself\u001b[0m\u001b[0;34m.\u001b[0m\u001b[0m_run_search\u001b[0m\u001b[0;34m(\u001b[0m\u001b[0mevaluate_candidates\u001b[0m\u001b[0;34m)\u001b[0m\u001b[0;34m\u001b[0m\u001b[0;34m\u001b[0m\u001b[0m\n\u001b[0m\u001b[1;32m    875\u001b[0m \u001b[0;34m\u001b[0m\u001b[0m\n\u001b[1;32m    876\u001b[0m             \u001b[0;31m# multimetric is determined here because in the case of a callable\u001b[0m\u001b[0;34m\u001b[0m\u001b[0;34m\u001b[0m\u001b[0m\n",
            "\u001b[0;32m/usr/local/lib/python3.10/dist-packages/sklearn/model_selection/_search.py\u001b[0m in \u001b[0;36m_run_search\u001b[0;34m(self, evaluate_candidates)\u001b[0m\n\u001b[1;32m   1386\u001b[0m     \u001b[0;32mdef\u001b[0m \u001b[0m_run_search\u001b[0m\u001b[0;34m(\u001b[0m\u001b[0mself\u001b[0m\u001b[0;34m,\u001b[0m \u001b[0mevaluate_candidates\u001b[0m\u001b[0;34m)\u001b[0m\u001b[0;34m:\u001b[0m\u001b[0;34m\u001b[0m\u001b[0;34m\u001b[0m\u001b[0m\n\u001b[1;32m   1387\u001b[0m         \u001b[0;34m\"\"\"Search all candidates in param_grid\"\"\"\u001b[0m\u001b[0;34m\u001b[0m\u001b[0;34m\u001b[0m\u001b[0m\n\u001b[0;32m-> 1388\u001b[0;31m         \u001b[0mevaluate_candidates\u001b[0m\u001b[0;34m(\u001b[0m\u001b[0mParameterGrid\u001b[0m\u001b[0;34m(\u001b[0m\u001b[0mself\u001b[0m\u001b[0;34m.\u001b[0m\u001b[0mparam_grid\u001b[0m\u001b[0;34m)\u001b[0m\u001b[0;34m)\u001b[0m\u001b[0;34m\u001b[0m\u001b[0;34m\u001b[0m\u001b[0m\n\u001b[0m\u001b[1;32m   1389\u001b[0m \u001b[0;34m\u001b[0m\u001b[0m\n\u001b[1;32m   1390\u001b[0m \u001b[0;34m\u001b[0m\u001b[0m\n",
            "\u001b[0;32m/usr/local/lib/python3.10/dist-packages/sklearn/model_selection/_search.py\u001b[0m in \u001b[0;36mevaluate_candidates\u001b[0;34m(candidate_params, cv, more_results)\u001b[0m\n\u001b[1;32m    849\u001b[0m                     )\n\u001b[1;32m    850\u001b[0m \u001b[0;34m\u001b[0m\u001b[0m\n\u001b[0;32m--> 851\u001b[0;31m                 \u001b[0m_warn_or_raise_about_fit_failures\u001b[0m\u001b[0;34m(\u001b[0m\u001b[0mout\u001b[0m\u001b[0;34m,\u001b[0m \u001b[0mself\u001b[0m\u001b[0;34m.\u001b[0m\u001b[0merror_score\u001b[0m\u001b[0;34m)\u001b[0m\u001b[0;34m\u001b[0m\u001b[0;34m\u001b[0m\u001b[0m\n\u001b[0m\u001b[1;32m    852\u001b[0m \u001b[0;34m\u001b[0m\u001b[0m\n\u001b[1;32m    853\u001b[0m                 \u001b[0;31m# For callable self.scoring, the return type is only know after\u001b[0m\u001b[0;34m\u001b[0m\u001b[0;34m\u001b[0m\u001b[0m\n",
            "\u001b[0;32m/usr/local/lib/python3.10/dist-packages/sklearn/model_selection/_validation.py\u001b[0m in \u001b[0;36m_warn_or_raise_about_fit_failures\u001b[0;34m(results, error_score)\u001b[0m\n\u001b[1;32m    365\u001b[0m                 \u001b[0;34mf\"Below are more details about the failures:\\n{fit_errors_summary}\"\u001b[0m\u001b[0;34m\u001b[0m\u001b[0;34m\u001b[0m\u001b[0m\n\u001b[1;32m    366\u001b[0m             )\n\u001b[0;32m--> 367\u001b[0;31m             \u001b[0;32mraise\u001b[0m \u001b[0mValueError\u001b[0m\u001b[0;34m(\u001b[0m\u001b[0mall_fits_failed_message\u001b[0m\u001b[0;34m)\u001b[0m\u001b[0;34m\u001b[0m\u001b[0;34m\u001b[0m\u001b[0m\n\u001b[0m\u001b[1;32m    368\u001b[0m \u001b[0;34m\u001b[0m\u001b[0m\n\u001b[1;32m    369\u001b[0m         \u001b[0;32melse\u001b[0m\u001b[0;34m:\u001b[0m\u001b[0;34m\u001b[0m\u001b[0;34m\u001b[0m\u001b[0m\n",
            "\u001b[0;31mValueError\u001b[0m: \nAll the 720 fits failed.\nIt is very likely that your model is misconfigured.\nYou can try to debug the error by setting error_score='raise'.\n\nBelow are more details about the failures:\n--------------------------------------------------------------------------------\n5 fits failed with the following error:\nTraceback (most recent call last):\n  File \"/usr/local/lib/python3.10/dist-packages/sklearn/model_selection/_validation.py\", line 686, in _fit_and_score\n    estimator.fit(X_train, y_train, **fit_params)\n  File \"/usr/local/lib/python3.10/dist-packages/xgboost/core.py\", line 730, in inner_f\n    return func(**kwargs)\n  File \"/usr/local/lib/python3.10/dist-packages/xgboost/sklearn.py\", line 1090, in fit\n    self._Booster = train(\n  File \"/usr/local/lib/python3.10/dist-packages/xgboost/core.py\", line 730, in inner_f\n    return func(**kwargs)\n  File \"/usr/local/lib/python3.10/dist-packages/xgboost/training.py\", line 181, in train\n    bst.update(dtrain, i, obj)\n  File \"/usr/local/lib/python3.10/dist-packages/xgboost/core.py\", line 2050, in update\n    _check_call(\n  File \"/usr/local/lib/python3.10/dist-packages/xgboost/core.py\", line 282, in _check_call\n    raise XGBoostError(py_str(_LIB.XGBGetLastError()))\nxgboost.core.XGBoostError: [19:44:39] /workspace/src/objective/objective.cc:27: Unknown objective function: `squaredeerror`\nObjective candidate: rank:ndcg\nObjective candidate: rank:pairwise\nObjective candidate: rank:map\nObjective candidate: survival:aft\nObjective candidate: binary:hinge\nObjective candidate: multi:softmax\nObjective candidate: multi:softprob\nObjective candidate: reg:quantileerror\nObjective candidate: reg:squarederror\nObjective candidate: reg:squaredlogerror\nObjective candidate: reg:logistic\nObjective candidate: binary:logistic\nObjective candidate: binary:logitraw\nObjective candidate: reg:linear\nObjective candidate: reg:pseudohubererror\nObjective candidate: count:poisson\nObjective candidate: survival:cox\nObjective candidate: reg:gamma\nObjective candidate: reg:tweedie\nObjective candidate: reg:absoluteerror\n\nStack trace:\n  [bt] (0) /usr/local/lib/python3.10/dist-packages/xgboost/lib/libxgboost.so(+0x1ba24e) [0x7ebdc8b2024e]\n  [bt] (1) /usr/local/lib/python3.10/dist-packages/xgboost/lib/libxgboost.so(+0x60c6ce) [0x7ebdc8f726ce]\n  [bt] (2) /usr/local/lib/python3.10/dist-packages/xgboost/lib/libxgboost.so(+0x4b9c3f) [0x7ebdc8e1fc3f]\n  [bt] (3) /usr/local/lib/python3.10/dist-packages/xgboost/lib/libxgboost.so(+0x4cccd3) [0x7ebdc8e32cd3]\n  [bt] (4) /usr/local/lib/python3.10/dist-packages/xgboost/lib/libxgboost.so(+0x4c5268) [0x7ebdc8e2b268]\n  [bt] (5) /usr/local/lib/python3.10/dist-packages/xgboost/lib/libxgboost.so(XGBoosterUpdateOneIter+0x70) [0x7ebdc8ac7ef0]\n  [bt] (6) /lib/x86_64-linux-gnu/libffi.so.8(+0x7e2e) [0x7ebe31e94e2e]\n  [bt] (7) /lib/x86_64-linux-gnu/libffi.so.8(+0x4493) [0x7ebe31e91493]\n  [bt] (8) /usr/lib/python3.10/lib-dynload/_ctypes.cpython-310-x86_64-linux-gnu.so(+0xa3e9) [0x7ebe31eba3e9]\n\n\n\n--------------------------------------------------------------------------------\n22 fits failed with the following error:\nTraceback (most recent call last):\n  File \"/usr/local/lib/python3.10/dist-packages/sklearn/model_selection/_validation.py\", line 686, in _fit_and_score\n    estimator.fit(X_train, y_train, **fit_params)\n  File \"/usr/local/lib/python3.10/dist-packages/xgboost/core.py\", line 730, in inner_f\n    return func(**kwargs)\n  File \"/usr/local/lib/python3.10/dist-packages/xgboost/sklearn.py\", line 1090, in fit\n    self._Booster = train(\n  File \"/usr/local/lib/python3.10/dist-packages/xgboost/core.py\", line 730, in inner_f\n    return func(**kwargs)\n  File \"/usr/local/lib/python3.10/dist-packages/xgboost/training.py\", line 181, in train\n    bst.update(dtrain, i, obj)\n  File \"/usr/local/lib/python3.10/dist-packages/xgboost/core.py\", line 2050, in update\n    _check_call(\n  File \"/usr/local/lib/python3.10/dist-packages/xgboost/core.py\", line 282, in _check_call\n    raise XGBoostError(py_str(_LIB.XGBGetLastError()))\nxgboost.core.XGBoostError: [19:44:40] /workspace/src/objective/objective.cc:27: Unknown objective function: `squaredeerror`\nObjective candidate: rank:ndcg\nObjective candidate: rank:pairwise\nObjective candidate: rank:map\nObjective candidate: survival:aft\nObjective candidate: binary:hinge\nObjective candidate: multi:softmax\nObjective candidate: multi:softprob\nObjective candidate: reg:quantileerror\nObjective candidate: reg:squarederror\nObjective candidate: reg:squaredlogerror\nObjective candidate: reg:logistic\nObjective candidate: binary:logistic\nObjective candidate: binary:logitraw\nObjective candidate: reg:linear\nObjective candidate: reg:pseudohubererror\nObjective candidate: count:poisson\nObjective candidate: survival:cox\nObjective candidate: reg:gamma\nObjective candidate: reg:tweedie\nObjective candidate: reg:absoluteerror\n\nStack trace:\n  [bt] (0) /usr/local/lib/python3.10/dist-packages/xgboost/lib/libxgboost.so(+0x1ba24e) [0x7ebdc8b2024e]\n  [bt] (1) /usr/local/lib/python3.10/dist-packages/xgboost/lib/libxgboost.so(+0x60c6ce) [0x7ebdc8f726ce]\n  [bt] (2) /usr/local/lib/python3.10/dist-packages/xgboost/lib/libxgboost.so(+0x4b9c3f) [0x7ebdc8e1fc3f]\n  [bt] (3) /usr/local/lib/python3.10/dist-packages/xgboost/lib/libxgboost.so(+0x4cccd3) [0x7ebdc8e32cd3]\n  [bt] (4) /usr/local/lib/python3.10/dist-packages/xgboost/lib/libxgboost.so(+0x4c5268) [0x7ebdc8e2b268]\n  [bt] (5) /usr/local/lib/python3.10/dist-packages/xgboost/lib/libxgboost.so(XGBoosterUpdateOneIter+0x70) [0x7ebdc8ac7ef0]\n  [bt] (6) /lib/x86_64-linux-gnu/libffi.so.8(+0x7e2e) [0x7ebe31e94e2e]\n  [bt] (7) /lib/x86_64-linux-gnu/libffi.so.8(+0x4493) [0x7ebe31e91493]\n  [bt] (8) /usr/lib/python3.10/lib-dynload/_ctypes.cpython-310-x86_64-linux-gnu.so(+0xa3e9) [0x7ebe31eba3e9]\n\n\n\n--------------------------------------------------------------------------------\n41 fits failed with the following error:\nTraceback (most recent call last):\n  File \"/usr/local/lib/python3.10/dist-packages/sklearn/model_selection/_validation.py\", line 686, in _fit_and_score\n    estimator.fit(X_train, y_train, **fit_params)\n  File \"/usr/local/lib/python3.10/dist-packages/xgboost/core.py\", line 730, in inner_f\n    return func(**kwargs)\n  File \"/usr/local/lib/python3.10/dist-packages/xgboost/sklearn.py\", line 1090, in fit\n    self._Booster = train(\n  File \"/usr/local/lib/python3.10/dist-packages/xgboost/core.py\", line 730, in inner_f\n    return func(**kwargs)\n  File \"/usr/local/lib/python3.10/dist-packages/xgboost/training.py\", line 181, in train\n    bst.update(dtrain, i, obj)\n  File \"/usr/local/lib/python3.10/dist-packages/xgboost/core.py\", line 2050, in update\n    _check_call(\n  File \"/usr/local/lib/python3.10/dist-packages/xgboost/core.py\", line 282, in _check_call\n    raise XGBoostError(py_str(_LIB.XGBGetLastError()))\nxgboost.core.XGBoostError: [19:44:41] /workspace/src/objective/objective.cc:27: Unknown objective function: `squaredeerror`\nObjective candidate: rank:ndcg\nObjective candidate: rank:pairwise\nObjective candidate: rank:map\nObjective candidate: survival:aft\nObjective candidate: binary:hinge\nObjective candidate: multi:softmax\nObjective candidate: multi:softprob\nObjective candidate: reg:quantileerror\nObjective candidate: reg:squarederror\nObjective candidate: reg:squaredlogerror\nObjective candidate: reg:logistic\nObjective candidate: binary:logistic\nObjective candidate: binary:logitraw\nObjective candidate: reg:linear\nObjective candidate: reg:pseudohubererror\nObjective candidate: count:poisson\nObjective candidate: survival:cox\nObjective candidate: reg:gamma\nObjective candidate: reg:tweedie\nObjective candidate: reg:absoluteerror\n\nStack trace:\n  [bt] (0) /usr/local/lib/python3.10/dist-packages/xgboost/lib/libxgboost.so(+0x1ba24e) [0x7ebdc8b2024e]\n  [bt] (1) /usr/local/lib/python3.10/dist-packages/xgboost/lib/libxgboost.so(+0x60c6ce) [0x7ebdc8f726ce]\n  [bt] (2) /usr/local/lib/python3.10/dist-packages/xgboost/lib/libxgboost.so(+0x4b9c3f) [0x7ebdc8e1fc3f]\n  [bt] (3) /usr/local/lib/python3.10/dist-packages/xgboost/lib/libxgboost.so(+0x4cccd3) [0x7ebdc8e32cd3]\n  [bt] (4) /usr/local/lib/python3.10/dist-packages/xgboost/lib/libxgboost.so(+0x4c5268) [0x7ebdc8e2b268]\n  [bt] (5) /usr/local/lib/python3.10/dist-packages/xgboost/lib/libxgboost.so(XGBoosterUpdateOneIter+0x70) [0x7ebdc8ac7ef0]\n  [bt] (6) /lib/x86_64-linux-gnu/libffi.so.8(+0x7e2e) [0x7ebe31e94e2e]\n  [bt] (7) /lib/x86_64-linux-gnu/libffi.so.8(+0x4493) [0x7ebe31e91493]\n  [bt] (8) /usr/lib/python3.10/lib-dynload/_ctypes.cpython-310-x86_64-linux-gnu.so(+0xa3e9) [0x7ebe31eba3e9]\n\n\n\n--------------------------------------------------------------------------------\n41 fits failed with the following error:\nTraceback (most recent call last):\n  File \"/usr/local/lib/python3.10/dist-packages/sklearn/model_selection/_validation.py\", line 686, in _fit_and_score\n    estimator.fit(X_train, y_train, **fit_params)\n  File \"/usr/local/lib/python3.10/dist-packages/xgboost/core.py\", line 730, in inner_f\n    return func(**kwargs)\n  File \"/usr/local/lib/python3.10/dist-packages/xgboost/sklearn.py\", line 1090, in fit\n    self._Booster = train(\n  File \"/usr/local/lib/python3.10/dist-packages/xgboost/core.py\", line 730, in inner_f\n    return func(**kwargs)\n  File \"/usr/local/lib/python3.10/dist-packages/xgboost/training.py\", line 181, in train\n    bst.update(dtrain, i, obj)\n  File \"/usr/local/lib/python3.10/dist-packages/xgboost/core.py\", line 2050, in update\n    _check_call(\n  File \"/usr/local/lib/python3.10/dist-packages/xgboost/core.py\", line 282, in _check_call\n    raise XGBoostError(py_str(_LIB.XGBGetLastError()))\nxgboost.core.XGBoostError: [19:44:42] /workspace/src/objective/objective.cc:27: Unknown objective function: `squaredeerror`\nObjective candidate: rank:ndcg\nObjective candidate: rank:pairwise\nObjective candidate: rank:map\nObjective candidate: survival:aft\nObjective candidate: binary:hinge\nObjective candidate: multi:softmax\nObjective candidate: multi:softprob\nObjective candidate: reg:quantileerror\nObjective candidate: reg:squarederror\nObjective candidate: reg:squaredlogerror\nObjective candidate: reg:logistic\nObjective candidate: binary:logistic\nObjective candidate: binary:logitraw\nObjective candidate: reg:linear\nObjective candidate: reg:pseudohubererror\nObjective candidate: count:poisson\nObjective candidate: survival:cox\nObjective candidate: reg:gamma\nObjective candidate: reg:tweedie\nObjective candidate: reg:absoluteerror\n\nStack trace:\n  [bt] (0) /usr/local/lib/python3.10/dist-packages/xgboost/lib/libxgboost.so(+0x1ba24e) [0x7ebdc8b2024e]\n  [bt] (1) /usr/local/lib/python3.10/dist-packages/xgboost/lib/libxgboost.so(+0x60c6ce) [0x7ebdc8f726ce]\n  [bt] (2) /usr/local/lib/python3.10/dist-packages/xgboost/lib/libxgboost.so(+0x4b9c3f) [0x7ebdc8e1fc3f]\n  [bt] (3) /usr/local/lib/python3.10/dist-packages/xgboost/lib/libxgboost.so(+0x4cccd3) [0x7ebdc8e32cd3]\n  [bt] (4) /usr/local/lib/python3.10/dist-packages/xgboost/lib/libxgboost.so(+0x4c5268) [0x7ebdc8e2b268]\n  [bt] (5) /usr/local/lib/python3.10/dist-packages/xgboost/lib/libxgboost.so(XGBoosterUpdateOneIter+0x70) [0x7ebdc8ac7ef0]\n  [bt] (6) /lib/x86_64-linux-gnu/libffi.so.8(+0x7e2e) [0x7ebe31e94e2e]\n  [bt] (7) /lib/x86_64-linux-gnu/libffi.so.8(+0x4493) [0x7ebe31e91493]\n  [bt] (8) /usr/lib/python3.10/lib-dynload/_ctypes.cpython-310-x86_64-linux-gnu.so(+0xa3e9) [0x7ebe31eba3e9]\n\n\n\n--------------------------------------------------------------------------------\n42 fits failed with the following error:\nTraceback (most recent call last):\n  File \"/usr/local/lib/python3.10/dist-packages/sklearn/model_selection/_validation.py\", line 686, in _fit_and_score\n    estimator.fit(X_train, y_train, **fit_params)\n  File \"/usr/local/lib/python3.10/dist-packages/xgboost/core.py\", line 730, in inner_f\n    return func(**kwargs)\n  File \"/usr/local/lib/python3.10/dist-packages/xgboost/sklearn.py\", line 1090, in fit\n    self._Booster = train(\n  File \"/usr/local/lib/python3.10/dist-packages/xgboost/core.py\", line 730, in inner_f\n    return func(**kwargs)\n  File \"/usr/local/lib/python3.10/dist-packages/xgboost/training.py\", line 181, in train\n    bst.update(dtrain, i, obj)\n  File \"/usr/local/lib/python3.10/dist-packages/xgboost/core.py\", line 2050, in update\n    _check_call(\n  File \"/usr/local/lib/python3.10/dist-packages/xgboost/core.py\", line 282, in _check_call\n    raise XGBoostError(py_str(_LIB.XGBGetLastError()))\nxgboost.core.XGBoostError: [19:44:43] /workspace/src/objective/objective.cc:27: Unknown objective function: `squaredeerror`\nObjective candidate: rank:ndcg\nObjective candidate: rank:pairwise\nObjective candidate: rank:map\nObjective candidate: survival:aft\nObjective candidate: binary:hinge\nObjective candidate: multi:softmax\nObjective candidate: multi:softprob\nObjective candidate: reg:quantileerror\nObjective candidate: reg:squarederror\nObjective candidate: reg:squaredlogerror\nObjective candidate: reg:logistic\nObjective candidate: binary:logistic\nObjective candidate: binary:logitraw\nObjective candidate: reg:linear\nObjective candidate: reg:pseudohubererror\nObjective candidate: count:poisson\nObjective candidate: survival:cox\nObjective candidate: reg:gamma\nObjective candidate: reg:tweedie\nObjective candidate: reg:absoluteerror\n\nStack trace:\n  [bt] (0) /usr/local/lib/python3.10/dist-packages/xgboost/lib/libxgboost.so(+0x1ba24e) [0x7ebdc8b2024e]\n  [bt] (1) /usr/local/lib/python3.10/dist-packages/xgboost/lib/libxgboost.so(+0x60c6ce) [0x7ebdc8f726ce]\n  [bt] (2) /usr/local/lib/python3.10/dist-packages/xgboost/lib/libxgboost.so(+0x4b9c3f) [0x7ebdc8e1fc3f]\n  [bt] (3) /usr/local/lib/python3.10/dist-packages/xgboost/lib/libxgboost.so(+0x4cccd3) [0x7ebdc8e32cd3]\n  [bt] (4) /usr/local/lib/python3.10/dist-packages/xgboost/lib/libxgboost.so(+0x4c5268) [0x7ebdc8e2b268]\n  [bt] (5) /usr/local/lib/python3.10/dist-packages/xgboost/lib/libxgboost.so(XGBoosterUpdateOneIter+0x70) [0x7ebdc8ac7ef0]\n  [bt] (6) /lib/x86_64-linux-gnu/libffi.so.8(+0x7e2e) [0x7ebe31e94e2e]\n  [bt] (7) /lib/x86_64-linux-gnu/libffi.so.8(+0x4493) [0x7ebe31e91493]\n  [bt] (8) /usr/lib/python3.10/lib-dynload/_ctypes.cpython-310-x86_64-linux-gnu.so(+0xa3e9) [0x7ebe31eba3e9]\n\n\n\n--------------------------------------------------------------------------------\n42 fits failed with the following error:\nTraceback (most recent call last):\n  File \"/usr/local/lib/python3.10/dist-packages/sklearn/model_selection/_validation.py\", line 686, in _fit_and_score\n    estimator.fit(X_train, y_train, **fit_params)\n  File \"/usr/local/lib/python3.10/dist-packages/xgboost/core.py\", line 730, in inner_f\n    return func(**kwargs)\n  File \"/usr/local/lib/python3.10/dist-packages/xgboost/sklearn.py\", line 1090, in fit\n    self._Booster = train(\n  File \"/usr/local/lib/python3.10/dist-packages/xgboost/core.py\", line 730, in inner_f\n    return func(**kwargs)\n  File \"/usr/local/lib/python3.10/dist-packages/xgboost/training.py\", line 181, in train\n    bst.update(dtrain, i, obj)\n  File \"/usr/local/lib/python3.10/dist-packages/xgboost/core.py\", line 2050, in update\n    _check_call(\n  File \"/usr/local/lib/python3.10/dist-packages/xgboost/core.py\", line 282, in _check_call\n    raise XGBoostError(py_str(_LIB.XGBGetLastError()))\nxgboost.core.XGBoostError: [19:44:44] /workspace/src/objective/objective.cc:27: Unknown objective function: `squaredeerror`\nObjective candidate: rank:ndcg\nObjective candidate: rank:pairwise\nObjective candidate: rank:map\nObjective candidate: survival:aft\nObjective candidate: binary:hinge\nObjective candidate: multi:softmax\nObjective candidate: multi:softprob\nObjective candidate: reg:quantileerror\nObjective candidate: reg:squarederror\nObjective candidate: reg:squaredlogerror\nObjective candidate: reg:logistic\nObjective candidate: binary:logistic\nObjective candidate: binary:logitraw\nObjective candidate: reg:linear\nObjective candidate: reg:pseudohubererror\nObjective candidate: count:poisson\nObjective candidate: survival:cox\nObjective candidate: reg:gamma\nObjective candidate: reg:tweedie\nObjective candidate: reg:absoluteerror\n\nStack trace:\n  [bt] (0) /usr/local/lib/python3.10/dist-packages/xgboost/lib/libxgboost.so(+0x1ba24e) [0x7ebdc8b2024e]\n  [bt] (1) /usr/local/lib/python3.10/dist-packages/xgboost/lib/libxgboost.so(+0x60c6ce) [0x7ebdc8f726ce]\n  [bt] (2) /usr/local/lib/python3.10/dist-packages/xgboost/lib/libxgboost.so(+0x4b9c3f) [0x7ebdc8e1fc3f]\n  [bt] (3) /usr/local/lib/python3.10/dist-packages/xgboost/lib/libxgboost.so(+0x4cccd3) [0x7ebdc8e32cd3]\n  [bt] (4) /usr/local/lib/python3.10/dist-packages/xgboost/lib/libxgboost.so(+0x4c5268) [0x7ebdc8e2b268]\n  [bt] (5) /usr/local/lib/python3.10/dist-packages/xgboost/lib/libxgboost.so(XGBoosterUpdateOneIter+0x70) [0x7ebdc8ac7ef0]\n  [bt] (6) /lib/x86_64-linux-gnu/libffi.so.8(+0x7e2e) [0x7ebe31e94e2e]\n  [bt] (7) /lib/x86_64-linux-gnu/libffi.so.8(+0x4493) [0x7ebe31e91493]\n  [bt] (8) /usr/lib/python3.10/lib-dynload/_ctypes.cpython-310-x86_64-linux-gnu.so(+0xa3e9) [0x7ebe31eba3e9]\n\n\n\n--------------------------------------------------------------------------------\n41 fits failed with the following error:\nTraceback (most recent call last):\n  File \"/usr/local/lib/python3.10/dist-packages/sklearn/model_selection/_validation.py\", line 686, in _fit_and_score\n    estimator.fit(X_train, y_train, **fit_params)\n  File \"/usr/local/lib/python3.10/dist-packages/xgboost/core.py\", line 730, in inner_f\n    return func(**kwargs)\n  File \"/usr/local/lib/python3.10/dist-packages/xgboost/sklearn.py\", line 1090, in fit\n    self._Booster = train(\n  File \"/usr/local/lib/python3.10/dist-packages/xgboost/core.py\", line 730, in inner_f\n    return func(**kwargs)\n  File \"/usr/local/lib/python3.10/dist-packages/xgboost/training.py\", line 181, in train\n    bst.update(dtrain, i, obj)\n  File \"/usr/local/lib/python3.10/dist-packages/xgboost/core.py\", line 2050, in update\n    _check_call(\n  File \"/usr/local/lib/python3.10/dist-packages/xgboost/core.py\", line 282, in _check_call\n    raise XGBoostError(py_str(_LIB.XGBGetLastError()))\nxgboost.core.XGBoostError: [19:44:45] /workspace/src/objective/objective.cc:27: Unknown objective function: `squaredeerror`\nObjective candidate: rank:ndcg\nObjective candidate: rank:pairwise\nObjective candidate: rank:map\nObjective candidate: survival:aft\nObjective candidate: binary:hinge\nObjective candidate: multi:softmax\nObjective candidate: multi:softprob\nObjective candidate: reg:quantileerror\nObjective candidate: reg:squarederror\nObjective candidate: reg:squaredlogerror\nObjective candidate: reg:logistic\nObjective candidate: binary:logistic\nObjective candidate: binary:logitraw\nObjective candidate: reg:linear\nObjective candidate: reg:pseudohubererror\nObjective candidate: count:poisson\nObjective candidate: survival:cox\nObjective candidate: reg:gamma\nObjective candidate: reg:tweedie\nObjective candidate: reg:absoluteerror\n\nStack trace:\n  [bt] (0) /usr/local/lib/python3.10/dist-packages/xgboost/lib/libxgboost.so(+0x1ba24e) [0x7ebdc8b2024e]\n  [bt] (1) /usr/local/lib/python3.10/dist-packages/xgboost/lib/libxgboost.so(+0x60c6ce) [0x7ebdc8f726ce]\n  [bt] (2) /usr/local/lib/python3.10/dist-packages/xgboost/lib/libxgboost.so(+0x4b9c3f) [0x7ebdc8e1fc3f]\n  [bt] (3) /usr/local/lib/python3.10/dist-packages/xgboost/lib/libxgboost.so(+0x4cccd3) [0x7ebdc8e32cd3]\n  [bt] (4) /usr/local/lib/python3.10/dist-packages/xgboost/lib/libxgboost.so(+0x4c5268) [0x7ebdc8e2b268]\n  [bt] (5) /usr/local/lib/python3.10/dist-packages/xgboost/lib/libxgboost.so(XGBoosterUpdateOneIter+0x70) [0x7ebdc8ac7ef0]\n  [bt] (6) /lib/x86_64-linux-gnu/libffi.so.8(+0x7e2e) [0x7ebe31e94e2e]\n  [bt] (7) /lib/x86_64-linux-gnu/libffi.so.8(+0x4493) [0x7ebe31e91493]\n  [bt] (8) /usr/lib/python3.10/lib-dynload/_ctypes.cpython-310-x86_64-linux-gnu.so(+0xa3e9) [0x7ebe31eba3e9]\n\n\n\n--------------------------------------------------------------------------------\n42 fits failed with the following error:\nTraceback (most recent call last):\n  File \"/usr/local/lib/python3.10/dist-packages/sklearn/model_selection/_validation.py\", line 686, in _fit_and_score\n    estimator.fit(X_train, y_train, **fit_params)\n  File \"/usr/local/lib/python3.10/dist-packages/xgboost/core.py\", line 730, in inner_f\n    return func(**kwargs)\n  File \"/usr/local/lib/python3.10/dist-packages/xgboost/sklearn.py\", line 1090, in fit\n    self._Booster = train(\n  File \"/usr/local/lib/python3.10/dist-packages/xgboost/core.py\", line 730, in inner_f\n    return func(**kwargs)\n  File \"/usr/local/lib/python3.10/dist-packages/xgboost/training.py\", line 181, in train\n    bst.update(dtrain, i, obj)\n  File \"/usr/local/lib/python3.10/dist-packages/xgboost/core.py\", line 2050, in update\n    _check_call(\n  File \"/usr/local/lib/python3.10/dist-packages/xgboost/core.py\", line 282, in _check_call\n    raise XGBoostError(py_str(_LIB.XGBGetLastError()))\nxgboost.core.XGBoostError: [19:44:46] /workspace/src/objective/objective.cc:27: Unknown objective function: `squaredeerror`\nObjective candidate: rank:ndcg\nObjective candidate: rank:pairwise\nObjective candidate: rank:map\nObjective candidate: survival:aft\nObjective candidate: binary:hinge\nObjective candidate: multi:softmax\nObjective candidate: multi:softprob\nObjective candidate: reg:quantileerror\nObjective candidate: reg:squarederror\nObjective candidate: reg:squaredlogerror\nObjective candidate: reg:logistic\nObjective candidate: binary:logistic\nObjective candidate: binary:logitraw\nObjective candidate: reg:linear\nObjective candidate: reg:pseudohubererror\nObjective candidate: count:poisson\nObjective candidate: survival:cox\nObjective candidate: reg:gamma\nObjective candidate: reg:tweedie\nObjective candidate: reg:absoluteerror\n\nStack trace:\n  [bt] (0) /usr/local/lib/python3.10/dist-packages/xgboost/lib/libxgboost.so(+0x1ba24e) [0x7ebdc8b2024e]\n  [bt] (1) /usr/local/lib/python3.10/dist-packages/xgboost/lib/libxgboost.so(+0x60c6ce) [0x7ebdc8f726ce]\n  [bt] (2) /usr/local/lib/python3.10/dist-packages/xgboost/lib/libxgboost.so(+0x4b9c3f) [0x7ebdc8e1fc3f]\n  [bt] (3) /usr/local/lib/python3.10/dist-packages/xgboost/lib/libxgboost.so(+0x4cccd3) [0x7ebdc8e32cd3]\n  [bt] (4) /usr/local/lib/python3.10/dist-packages/xgboost/lib/libxgboost.so(+0x4c5268) [0x7ebdc8e2b268]\n  [bt] (5) /usr/local/lib/python3.10/dist-packages/xgboost/lib/libxgboost.so(XGBoosterUpdateOneIter+0x70) [0x7ebdc8ac7ef0]\n  [bt] (6) /lib/x86_64-linux-gnu/libffi.so.8(+0x7e2e) [0x7ebe31e94e2e]\n  [bt] (7) /lib/x86_64-linux-gnu/libffi.so.8(+0x4493) [0x7ebe31e91493]\n  [bt] (8) /usr/lib/python3.10/lib-dynload/_ctypes.cpython-310-x86_64-linux-gnu.so(+0xa3e9) [0x7ebe31eba3e9]\n\n\n\n--------------------------------------------------------------------------------\n41 fits failed with the following error:\nTraceback (most recent call last):\n  File \"/usr/local/lib/python3.10/dist-packages/sklearn/model_selection/_validation.py\", line 686, in _fit_and_score\n    estimator.fit(X_train, y_train, **fit_params)\n  File \"/usr/local/lib/python3.10/dist-packages/xgboost/core.py\", line 730, in inner_f\n    return func(**kwargs)\n  File \"/usr/local/lib/python3.10/dist-packages/xgboost/sklearn.py\", line 1090, in fit\n    self._Booster = train(\n  File \"/usr/local/lib/python3.10/dist-packages/xgboost/core.py\", line 730, in inner_f\n    return func(**kwargs)\n  File \"/usr/local/lib/python3.10/dist-packages/xgboost/training.py\", line 181, in train\n    bst.update(dtrain, i, obj)\n  File \"/usr/local/lib/python3.10/dist-packages/xgboost/core.py\", line 2050, in update\n    _check_call(\n  File \"/usr/local/lib/python3.10/dist-packages/xgboost/core.py\", line 282, in _check_call\n    raise XGBoostError(py_str(_LIB.XGBGetLastError()))\nxgboost.core.XGBoostError: [19:44:47] /workspace/src/objective/objective.cc:27: Unknown objective function: `squaredeerror`\nObjective candidate: rank:ndcg\nObjective candidate: rank:pairwise\nObjective candidate: rank:map\nObjective candidate: survival:aft\nObjective candidate: binary:hinge\nObjective candidate: multi:softmax\nObjective candidate: multi:softprob\nObjective candidate: reg:quantileerror\nObjective candidate: reg:squarederror\nObjective candidate: reg:squaredlogerror\nObjective candidate: reg:logistic\nObjective candidate: binary:logistic\nObjective candidate: binary:logitraw\nObjective candidate: reg:linear\nObjective candidate: reg:pseudohubererror\nObjective candidate: count:poisson\nObjective candidate: survival:cox\nObjective candidate: reg:gamma\nObjective candidate: reg:tweedie\nObjective candidate: reg:absoluteerror\n\nStack trace:\n  [bt] (0) /usr/local/lib/python3.10/dist-packages/xgboost/lib/libxgboost.so(+0x1ba24e) [0x7ebdc8b2024e]\n  [bt] (1) /usr/local/lib/python3.10/dist-packages/xgboost/lib/libxgboost.so(+0x60c6ce) [0x7ebdc8f726ce]\n  [bt] (2) /usr/local/lib/python3.10/dist-packages/xgboost/lib/libxgboost.so(+0x4b9c3f) [0x7ebdc8e1fc3f]\n  [bt] (3) /usr/local/lib/python3.10/dist-packages/xgboost/lib/libxgboost.so(+0x4cccd3) [0x7ebdc8e32cd3]\n  [bt] (4) /usr/local/lib/python3.10/dist-packages/xgboost/lib/libxgboost.so(+0x4c5268) [0x7ebdc8e2b268]\n  [bt] (5) /usr/local/lib/python3.10/dist-packages/xgboost/lib/libxgboost.so(XGBoosterUpdateOneIter+0x70) [0x7ebdc8ac7ef0]\n  [bt] (6) /lib/x86_64-linux-gnu/libffi.so.8(+0x7e2e) [0x7ebe31e94e2e]\n  [bt] (7) /lib/x86_64-linux-gnu/libffi.so.8(+0x4493) [0x7ebe31e91493]\n  [bt] (8) /usr/lib/python3.10/lib-dynload/_ctypes.cpython-310-x86_64-linux-gnu.so(+0xa3e9) [0x7ebe31eba3e9]\n\n\n\n--------------------------------------------------------------------------------\n42 fits failed with the following error:\nTraceback (most recent call last):\n  File \"/usr/local/lib/python3.10/dist-packages/sklearn/model_selection/_validation.py\", line 686, in _fit_and_score\n    estimator.fit(X_train, y_train, **fit_params)\n  File \"/usr/local/lib/python3.10/dist-packages/xgboost/core.py\", line 730, in inner_f\n    return func(**kwargs)\n  File \"/usr/local/lib/python3.10/dist-packages/xgboost/sklearn.py\", line 1090, in fit\n    self._Booster = train(\n  File \"/usr/local/lib/python3.10/dist-packages/xgboost/core.py\", line 730, in inner_f\n    return func(**kwargs)\n  File \"/usr/local/lib/python3.10/dist-packages/xgboost/training.py\", line 181, in train\n    bst.update(dtrain, i, obj)\n  File \"/usr/local/lib/python3.10/dist-packages/xgboost/core.py\", line 2050, in update\n    _check_call(\n  File \"/usr/local/lib/python3.10/dist-packages/xgboost/core.py\", line 282, in _check_call\n    raise XGBoostError(py_str(_LIB.XGBGetLastError()))\nxgboost.core.XGBoostError: [19:44:48] /workspace/src/objective/objective.cc:27: Unknown objective function: `squaredeerror`\nObjective candidate: rank:ndcg\nObjective candidate: rank:pairwise\nObjective candidate: rank:map\nObjective candidate: survival:aft\nObjective candidate: binary:hinge\nObjective candidate: multi:softmax\nObjective candidate: multi:softprob\nObjective candidate: reg:quantileerror\nObjective candidate: reg:squarederror\nObjective candidate: reg:squaredlogerror\nObjective candidate: reg:logistic\nObjective candidate: binary:logistic\nObjective candidate: binary:logitraw\nObjective candidate: reg:linear\nObjective candidate: reg:pseudohubererror\nObjective candidate: count:poisson\nObjective candidate: survival:cox\nObjective candidate: reg:gamma\nObjective candidate: reg:tweedie\nObjective candidate: reg:absoluteerror\n\nStack trace:\n  [bt] (0) /usr/local/lib/python3.10/dist-packages/xgboost/lib/libxgboost.so(+0x1ba24e) [0x7ebdc8b2024e]\n  [bt] (1) /usr/local/lib/python3.10/dist-packages/xgboost/lib/libxgboost.so(+0x60c6ce) [0x7ebdc8f726ce]\n  [bt] (2) /usr/local/lib/python3.10/dist-packages/xgboost/lib/libxgboost.so(+0x4b9c3f) [0x7ebdc8e1fc3f]\n  [bt] (3) /usr/local/lib/python3.10/dist-packages/xgboost/lib/libxgboost.so(+0x4cccd3) [0x7ebdc8e32cd3]\n  [bt] (4) /usr/local/lib/python3.10/dist-packages/xgboost/lib/libxgboost.so(+0x4c5268) [0x7ebdc8e2b268]\n  [bt] (5) /usr/local/lib/python3.10/dist-packages/xgboost/lib/libxgboost.so(XGBoosterUpdateOneIter+0x70) [0x7ebdc8ac7ef0]\n  [bt] (6) /lib/x86_64-linux-gnu/libffi.so.8(+0x7e2e) [0x7ebe31e94e2e]\n  [bt] (7) /lib/x86_64-linux-gnu/libffi.so.8(+0x4493) [0x7ebe31e91493]\n  [bt] (8) /usr/lib/python3.10/lib-dynload/_ctypes.cpython-310-x86_64-linux-gnu.so(+0xa3e9) [0x7ebe31eba3e9]\n\n\n\n--------------------------------------------------------------------------------\n41 fits failed with the following error:\nTraceback (most recent call last):\n  File \"/usr/local/lib/python3.10/dist-packages/sklearn/model_selection/_validation.py\", line 686, in _fit_and_score\n    estimator.fit(X_train, y_train, **fit_params)\n  File \"/usr/local/lib/python3.10/dist-packages/xgboost/core.py\", line 730, in inner_f\n    return func(**kwargs)\n  File \"/usr/local/lib/python3.10/dist-packages/xgboost/sklearn.py\", line 1090, in fit\n    self._Booster = train(\n  File \"/usr/local/lib/python3.10/dist-packages/xgboost/core.py\", line 730, in inner_f\n    return func(**kwargs)\n  File \"/usr/local/lib/python3.10/dist-packages/xgboost/training.py\", line 181, in train\n    bst.update(dtrain, i, obj)\n  File \"/usr/local/lib/python3.10/dist-packages/xgboost/core.py\", line 2050, in update\n    _check_call(\n  File \"/usr/local/lib/python3.10/dist-packages/xgboost/core.py\", line 282, in _check_call\n    raise XGBoostError(py_str(_LIB.XGBGetLastError()))\nxgboost.core.XGBoostError: [19:44:49] /workspace/src/objective/objective.cc:27: Unknown objective function: `squaredeerror`\nObjective candidate: rank:ndcg\nObjective candidate: rank:pairwise\nObjective candidate: rank:map\nObjective candidate: survival:aft\nObjective candidate: binary:hinge\nObjective candidate: multi:softmax\nObjective candidate: multi:softprob\nObjective candidate: reg:quantileerror\nObjective candidate: reg:squarederror\nObjective candidate: reg:squaredlogerror\nObjective candidate: reg:logistic\nObjective candidate: binary:logistic\nObjective candidate: binary:logitraw\nObjective candidate: reg:linear\nObjective candidate: reg:pseudohubererror\nObjective candidate: count:poisson\nObjective candidate: survival:cox\nObjective candidate: reg:gamma\nObjective candidate: reg:tweedie\nObjective candidate: reg:absoluteerror\n\nStack trace:\n  [bt] (0) /usr/local/lib/python3.10/dist-packages/xgboost/lib/libxgboost.so(+0x1ba24e) [0x7ebdc8b2024e]\n  [bt] (1) /usr/local/lib/python3.10/dist-packages/xgboost/lib/libxgboost.so(+0x60c6ce) [0x7ebdc8f726ce]\n  [bt] (2) /usr/local/lib/python3.10/dist-packages/xgboost/lib/libxgboost.so(+0x4b9c3f) [0x7ebdc8e1fc3f]\n  [bt] (3) /usr/local/lib/python3.10/dist-packages/xgboost/lib/libxgboost.so(+0x4cccd3) [0x7ebdc8e32cd3]\n  [bt] (4) /usr/local/lib/python3.10/dist-packages/xgboost/lib/libxgboost.so(+0x4c5268) [0x7ebdc8e2b268]\n  [bt] (5) /usr/local/lib/python3.10/dist-packages/xgboost/lib/libxgboost.so(XGBoosterUpdateOneIter+0x70) [0x7ebdc8ac7ef0]\n  [bt] (6) /lib/x86_64-linux-gnu/libffi.so.8(+0x7e2e) [0x7ebe31e94e2e]\n  [bt] (7) /lib/x86_64-linux-gnu/libffi.so.8(+0x4493) [0x7ebe31e91493]\n  [bt] (8) /usr/lib/python3.10/lib-dynload/_ctypes.cpython-310-x86_64-linux-gnu.so(+0xa3e9) [0x7ebe31eba3e9]\n\n\n\n--------------------------------------------------------------------------------\n32 fits failed with the following error:\nTraceback (most recent call last):\n  File \"/usr/local/lib/python3.10/dist-packages/sklearn/model_selection/_validation.py\", line 686, in _fit_and_score\n    estimator.fit(X_train, y_train, **fit_params)\n  File \"/usr/local/lib/python3.10/dist-packages/xgboost/core.py\", line 730, in inner_f\n    return func(**kwargs)\n  File \"/usr/local/lib/python3.10/dist-packages/xgboost/sklearn.py\", line 1090, in fit\n    self._Booster = train(\n  File \"/usr/local/lib/python3.10/dist-packages/xgboost/core.py\", line 730, in inner_f\n    return func(**kwargs)\n  File \"/usr/local/lib/python3.10/dist-packages/xgboost/training.py\", line 181, in train\n    bst.update(dtrain, i, obj)\n  File \"/usr/local/lib/python3.10/dist-packages/xgboost/core.py\", line 2050, in update\n    _check_call(\n  File \"/usr/local/lib/python3.10/dist-packages/xgboost/core.py\", line 282, in _check_call\n    raise XGBoostError(py_str(_LIB.XGBGetLastError()))\nxgboost.core.XGBoostError: [19:44:50] /workspace/src/objective/objective.cc:27: Unknown objective function: `squaredeerror`\nObjective candidate: rank:ndcg\nObjective candidate: rank:pairwise\nObjective candidate: rank:map\nObjective candidate: survival:aft\nObjective candidate: binary:hinge\nObjective candidate: multi:softmax\nObjective candidate: multi:softprob\nObjective candidate: reg:quantileerror\nObjective candidate: reg:squarederror\nObjective candidate: reg:squaredlogerror\nObjective candidate: reg:logistic\nObjective candidate: binary:logistic\nObjective candidate: binary:logitraw\nObjective candidate: reg:linear\nObjective candidate: reg:pseudohubererror\nObjective candidate: count:poisson\nObjective candidate: survival:cox\nObjective candidate: reg:gamma\nObjective candidate: reg:tweedie\nObjective candidate: reg:absoluteerror\n\nStack trace:\n  [bt] (0) /usr/local/lib/python3.10/dist-packages/xgboost/lib/libxgboost.so(+0x1ba24e) [0x7ebdc8b2024e]\n  [bt] (1) /usr/local/lib/python3.10/dist-packages/xgboost/lib/libxgboost.so(+0x60c6ce) [0x7ebdc8f726ce]\n  [bt] (2) /usr/local/lib/python3.10/dist-packages/xgboost/lib/libxgboost.so(+0x4b9c3f) [0x7ebdc8e1fc3f]\n  [bt] (3) /usr/local/lib/python3.10/dist-packages/xgboost/lib/libxgboost.so(+0x4cccd3) [0x7ebdc8e32cd3]\n  [bt] (4) /usr/local/lib/python3.10/dist-packages/xgboost/lib/libxgboost.so(+0x4c5268) [0x7ebdc8e2b268]\n  [bt] (5) /usr/local/lib/python3.10/dist-packages/xgboost/lib/libxgboost.so(XGBoosterUpdateOneIter+0x70) [0x7ebdc8ac7ef0]\n  [bt] (6) /lib/x86_64-linux-gnu/libffi.so.8(+0x7e2e) [0x7ebe31e94e2e]\n  [bt] (7) /lib/x86_64-linux-gnu/libffi.so.8(+0x4493) [0x7ebe31e91493]\n  [bt] (8) /usr/lib/python3.10/lib-dynload/_ctypes.cpython-310-x86_64-linux-gnu.so(+0xa3e9) [0x7ebe31eba3e9]\n\n\n\n--------------------------------------------------------------------------------\n11 fits failed with the following error:\nTraceback (most recent call last):\n  File \"/usr/local/lib/python3.10/dist-packages/sklearn/model_selection/_validation.py\", line 686, in _fit_and_score\n    estimator.fit(X_train, y_train, **fit_params)\n  File \"/usr/local/lib/python3.10/dist-packages/xgboost/core.py\", line 730, in inner_f\n    return func(**kwargs)\n  File \"/usr/local/lib/python3.10/dist-packages/xgboost/sklearn.py\", line 1090, in fit\n    self._Booster = train(\n  File \"/usr/local/lib/python3.10/dist-packages/xgboost/core.py\", line 730, in inner_f\n    return func(**kwargs)\n  File \"/usr/local/lib/python3.10/dist-packages/xgboost/training.py\", line 181, in train\n    bst.update(dtrain, i, obj)\n  File \"/usr/local/lib/python3.10/dist-packages/xgboost/core.py\", line 2050, in update\n    _check_call(\n  File \"/usr/local/lib/python3.10/dist-packages/xgboost/core.py\", line 282, in _check_call\n    raise XGBoostError(py_str(_LIB.XGBGetLastError()))\nxgboost.core.XGBoostError: [19:44:51] /workspace/src/objective/objective.cc:27: Unknown objective function: `squaredeerror`\nObjective candidate: rank:ndcg\nObjective candidate: rank:pairwise\nObjective candidate: rank:map\nObjective candidate: survival:aft\nObjective candidate: binary:hinge\nObjective candidate: multi:softmax\nObjective candidate: multi:softprob\nObjective candidate: reg:quantileerror\nObjective candidate: reg:squarederror\nObjective candidate: reg:squaredlogerror\nObjective candidate: reg:logistic\nObjective candidate: binary:logistic\nObjective candidate: binary:logitraw\nObjective candidate: reg:linear\nObjective candidate: reg:pseudohubererror\nObjective candidate: count:poisson\nObjective candidate: survival:cox\nObjective candidate: reg:gamma\nObjective candidate: reg:tweedie\nObjective candidate: reg:absoluteerror\n\nStack trace:\n  [bt] (0) /usr/local/lib/python3.10/dist-packages/xgboost/lib/libxgboost.so(+0x1ba24e) [0x7ebdc8b2024e]\n  [bt] (1) /usr/local/lib/python3.10/dist-packages/xgboost/lib/libxgboost.so(+0x60c6ce) [0x7ebdc8f726ce]\n  [bt] (2) /usr/local/lib/python3.10/dist-packages/xgboost/lib/libxgboost.so(+0x4b9c3f) [0x7ebdc8e1fc3f]\n  [bt] (3) /usr/local/lib/python3.10/dist-packages/xgboost/lib/libxgboost.so(+0x4cccd3) [0x7ebdc8e32cd3]\n  [bt] (4) /usr/local/lib/python3.10/dist-packages/xgboost/lib/libxgboost.so(+0x4c5268) [0x7ebdc8e2b268]\n  [bt] (5) /usr/local/lib/python3.10/dist-packages/xgboost/lib/libxgboost.so(XGBoosterUpdateOneIter+0x70) [0x7ebdc8ac7ef0]\n  [bt] (6) /lib/x86_64-linux-gnu/libffi.so.8(+0x7e2e) [0x7ebe31e94e2e]\n  [bt] (7) /lib/x86_64-linux-gnu/libffi.so.8(+0x4493) [0x7ebe31e91493]\n  [bt] (8) /usr/lib/python3.10/lib-dynload/_ctypes.cpython-310-x86_64-linux-gnu.so(+0xa3e9) [0x7ebe31eba3e9]\n\n\n\n--------------------------------------------------------------------------------\n11 fits failed with the following error:\nTraceback (most recent call last):\n  File \"/usr/local/lib/python3.10/dist-packages/sklearn/model_selection/_validation.py\", line 686, in _fit_and_score\n    estimator.fit(X_train, y_train, **fit_params)\n  File \"/usr/local/lib/python3.10/dist-packages/xgboost/core.py\", line 730, in inner_f\n    return func(**kwargs)\n  File \"/usr/local/lib/python3.10/dist-packages/xgboost/sklearn.py\", line 1090, in fit\n    self._Booster = train(\n  File \"/usr/local/lib/python3.10/dist-packages/xgboost/core.py\", line 730, in inner_f\n    return func(**kwargs)\n  File \"/usr/local/lib/python3.10/dist-packages/xgboost/training.py\", line 181, in train\n    bst.update(dtrain, i, obj)\n  File \"/usr/local/lib/python3.10/dist-packages/xgboost/core.py\", line 2050, in update\n    _check_call(\n  File \"/usr/local/lib/python3.10/dist-packages/xgboost/core.py\", line 282, in _check_call\n    raise XGBoostError(py_str(_LIB.XGBGetLastError()))\nxgboost.core.XGBoostError: [19:44:52] /workspace/src/objective/objective.cc:27: Unknown objective function: `squaredeerror`\nObjective candidate: rank:ndcg\nObjective candidate: rank:pairwise\nObjective candidate: rank:map\nObjective candidate: survival:aft\nObjective candidate: binary:hinge\nObjective candidate: multi:softmax\nObjective candidate: multi:softprob\nObjective candidate: reg:quantileerror\nObjective candidate: reg:squarederror\nObjective candidate: reg:squaredlogerror\nObjective candidate: reg:logistic\nObjective candidate: binary:logistic\nObjective candidate: binary:logitraw\nObjective candidate: reg:linear\nObjective candidate: reg:pseudohubererror\nObjective candidate: count:poisson\nObjective candidate: survival:cox\nObjective candidate: reg:gamma\nObjective candidate: reg:tweedie\nObjective candidate: reg:absoluteerror\n\nStack trace:\n  [bt] (0) /usr/local/lib/python3.10/dist-packages/xgboost/lib/libxgboost.so(+0x1ba24e) [0x7ebdc8b2024e]\n  [bt] (1) /usr/local/lib/python3.10/dist-packages/xgboost/lib/libxgboost.so(+0x60c6ce) [0x7ebdc8f726ce]\n  [bt] (2) /usr/local/lib/python3.10/dist-packages/xgboost/lib/libxgboost.so(+0x4b9c3f) [0x7ebdc8e1fc3f]\n  [bt] (3) /usr/local/lib/python3.10/dist-packages/xgboost/lib/libxgboost.so(+0x4cccd3) [0x7ebdc8e32cd3]\n  [bt] (4) /usr/local/lib/python3.10/dist-packages/xgboost/lib/libxgboost.so(+0x4c5268) [0x7ebdc8e2b268]\n  [bt] (5) /usr/local/lib/python3.10/dist-packages/xgboost/lib/libxgboost.so(XGBoosterUpdateOneIter+0x70) [0x7ebdc8ac7ef0]\n  [bt] (6) /lib/x86_64-linux-gnu/libffi.so.8(+0x7e2e) [0x7ebe31e94e2e]\n  [bt] (7) /lib/x86_64-linux-gnu/libffi.so.8(+0x4493) [0x7ebe31e91493]\n  [bt] (8) /usr/lib/python3.10/lib-dynload/_ctypes.cpython-310-x86_64-linux-gnu.so(+0xa3e9) [0x7ebe31eba3e9]\n\n\n\n--------------------------------------------------------------------------------\n32 fits failed with the following error:\nTraceback (most recent call last):\n  File \"/usr/local/lib/python3.10/dist-packages/sklearn/model_selection/_validation.py\", line 686, in _fit_and_score\n    estimator.fit(X_train, y_train, **fit_params)\n  File \"/usr/local/lib/python3.10/dist-packages/xgboost/core.py\", line 730, in inner_f\n    return func(**kwargs)\n  File \"/usr/local/lib/python3.10/dist-packages/xgboost/sklearn.py\", line 1090, in fit\n    self._Booster = train(\n  File \"/usr/local/lib/python3.10/dist-packages/xgboost/core.py\", line 730, in inner_f\n    return func(**kwargs)\n  File \"/usr/local/lib/python3.10/dist-packages/xgboost/training.py\", line 181, in train\n    bst.update(dtrain, i, obj)\n  File \"/usr/local/lib/python3.10/dist-packages/xgboost/core.py\", line 2050, in update\n    _check_call(\n  File \"/usr/local/lib/python3.10/dist-packages/xgboost/core.py\", line 282, in _check_call\n    raise XGBoostError(py_str(_LIB.XGBGetLastError()))\nxgboost.core.XGBoostError: [19:44:53] /workspace/src/objective/objective.cc:27: Unknown objective function: `squaredeerror`\nObjective candidate: rank:ndcg\nObjective candidate: rank:pairwise\nObjective candidate: rank:map\nObjective candidate: survival:aft\nObjective candidate: binary:hinge\nObjective candidate: multi:softmax\nObjective candidate: multi:softprob\nObjective candidate: reg:quantileerror\nObjective candidate: reg:squarederror\nObjective candidate: reg:squaredlogerror\nObjective candidate: reg:logistic\nObjective candidate: binary:logistic\nObjective candidate: binary:logitraw\nObjective candidate: reg:linear\nObjective candidate: reg:pseudohubererror\nObjective candidate: count:poisson\nObjective candidate: survival:cox\nObjective candidate: reg:gamma\nObjective candidate: reg:tweedie\nObjective candidate: reg:absoluteerror\n\nStack trace:\n  [bt] (0) /usr/local/lib/python3.10/dist-packages/xgboost/lib/libxgboost.so(+0x1ba24e) [0x7ebdc8b2024e]\n  [bt] (1) /usr/local/lib/python3.10/dist-packages/xgboost/lib/libxgboost.so(+0x60c6ce) [0x7ebdc8f726ce]\n  [bt] (2) /usr/local/lib/python3.10/dist-packages/xgboost/lib/libxgboost.so(+0x4b9c3f) [0x7ebdc8e1fc3f]\n  [bt] (3) /usr/local/lib/python3.10/dist-packages/xgboost/lib/libxgboost.so(+0x4cccd3) [0x7ebdc8e32cd3]\n  [bt] (4) /usr/local/lib/python3.10/dist-packages/xgboost/lib/libxgboost.so(+0x4c5268) [0x7ebdc8e2b268]\n  [bt] (5) /usr/local/lib/python3.10/dist-packages/xgboost/lib/libxgboost.so(XGBoosterUpdateOneIter+0x70) [0x7ebdc8ac7ef0]\n  [bt] (6) /lib/x86_64-linux-gnu/libffi.so.8(+0x7e2e) [0x7ebe31e94e2e]\n  [bt] (7) /lib/x86_64-linux-gnu/libffi.so.8(+0x4493) [0x7ebe31e91493]\n  [bt] (8) /usr/lib/python3.10/lib-dynload/_ctypes.cpython-310-x86_64-linux-gnu.so(+0xa3e9) [0x7ebe31eba3e9]\n\n\n\n--------------------------------------------------------------------------------\n42 fits failed with the following error:\nTraceback (most recent call last):\n  File \"/usr/local/lib/python3.10/dist-packages/sklearn/model_selection/_validation.py\", line 686, in _fit_and_score\n    estimator.fit(X_train, y_train, **fit_params)\n  File \"/usr/local/lib/python3.10/dist-packages/xgboost/core.py\", line 730, in inner_f\n    return func(**kwargs)\n  File \"/usr/local/lib/python3.10/dist-packages/xgboost/sklearn.py\", line 1090, in fit\n    self._Booster = train(\n  File \"/usr/local/lib/python3.10/dist-packages/xgboost/core.py\", line 730, in inner_f\n    return func(**kwargs)\n  File \"/usr/local/lib/python3.10/dist-packages/xgboost/training.py\", line 181, in train\n    bst.update(dtrain, i, obj)\n  File \"/usr/local/lib/python3.10/dist-packages/xgboost/core.py\", line 2050, in update\n    _check_call(\n  File \"/usr/local/lib/python3.10/dist-packages/xgboost/core.py\", line 282, in _check_call\n    raise XGBoostError(py_str(_LIB.XGBGetLastError()))\nxgboost.core.XGBoostError: [19:44:54] /workspace/src/objective/objective.cc:27: Unknown objective function: `squaredeerror`\nObjective candidate: rank:ndcg\nObjective candidate: rank:pairwise\nObjective candidate: rank:map\nObjective candidate: survival:aft\nObjective candidate: binary:hinge\nObjective candidate: multi:softmax\nObjective candidate: multi:softprob\nObjective candidate: reg:quantileerror\nObjective candidate: reg:squarederror\nObjective candidate: reg:squaredlogerror\nObjective candidate: reg:logistic\nObjective candidate: binary:logistic\nObjective candidate: binary:logitraw\nObjective candidate: reg:linear\nObjective candidate: reg:pseudohubererror\nObjective candidate: count:poisson\nObjective candidate: survival:cox\nObjective candidate: reg:gamma\nObjective candidate: reg:tweedie\nObjective candidate: reg:absoluteerror\n\nStack trace:\n  [bt] (0) /usr/local/lib/python3.10/dist-packages/xgboost/lib/libxgboost.so(+0x1ba24e) [0x7ebdc8b2024e]\n  [bt] (1) /usr/local/lib/python3.10/dist-packages/xgboost/lib/libxgboost.so(+0x60c6ce) [0x7ebdc8f726ce]\n  [bt] (2) /usr/local/lib/python3.10/dist-packages/xgboost/lib/libxgboost.so(+0x4b9c3f) [0x7ebdc8e1fc3f]\n  [bt] (3) /usr/local/lib/python3.10/dist-packages/xgboost/lib/libxgboost.so(+0x4cccd3) [0x7ebdc8e32cd3]\n  [bt] (4) /usr/local/lib/python3.10/dist-packages/xgboost/lib/libxgboost.so(+0x4c5268) [0x7ebdc8e2b268]\n  [bt] (5) /usr/local/lib/python3.10/dist-packages/xgboost/lib/libxgboost.so(XGBoosterUpdateOneIter+0x70) [0x7ebdc8ac7ef0]\n  [bt] (6) /lib/x86_64-linux-gnu/libffi.so.8(+0x7e2e) [0x7ebe31e94e2e]\n  [bt] (7) /lib/x86_64-linux-gnu/libffi.so.8(+0x4493) [0x7ebe31e91493]\n  [bt] (8) /usr/lib/python3.10/lib-dynload/_ctypes.cpython-310-x86_64-linux-gnu.so(+0xa3e9) [0x7ebe31eba3e9]\n\n\n\n--------------------------------------------------------------------------------\n41 fits failed with the following error:\nTraceback (most recent call last):\n  File \"/usr/local/lib/python3.10/dist-packages/sklearn/model_selection/_validation.py\", line 686, in _fit_and_score\n    estimator.fit(X_train, y_train, **fit_params)\n  File \"/usr/local/lib/python3.10/dist-packages/xgboost/core.py\", line 730, in inner_f\n    return func(**kwargs)\n  File \"/usr/local/lib/python3.10/dist-packages/xgboost/sklearn.py\", line 1090, in fit\n    self._Booster = train(\n  File \"/usr/local/lib/python3.10/dist-packages/xgboost/core.py\", line 730, in inner_f\n    return func(**kwargs)\n  File \"/usr/local/lib/python3.10/dist-packages/xgboost/training.py\", line 181, in train\n    bst.update(dtrain, i, obj)\n  File \"/usr/local/lib/python3.10/dist-packages/xgboost/core.py\", line 2050, in update\n    _check_call(\n  File \"/usr/local/lib/python3.10/dist-packages/xgboost/core.py\", line 282, in _check_call\n    raise XGBoostError(py_str(_LIB.XGBGetLastError()))\nxgboost.core.XGBoostError: [19:44:55] /workspace/src/objective/objective.cc:27: Unknown objective function: `squaredeerror`\nObjective candidate: rank:ndcg\nObjective candidate: rank:pairwise\nObjective candidate: rank:map\nObjective candidate: survival:aft\nObjective candidate: binary:hinge\nObjective candidate: multi:softmax\nObjective candidate: multi:softprob\nObjective candidate: reg:quantileerror\nObjective candidate: reg:squarederror\nObjective candidate: reg:squaredlogerror\nObjective candidate: reg:logistic\nObjective candidate: binary:logistic\nObjective candidate: binary:logitraw\nObjective candidate: reg:linear\nObjective candidate: reg:pseudohubererror\nObjective candidate: count:poisson\nObjective candidate: survival:cox\nObjective candidate: reg:gamma\nObjective candidate: reg:tweedie\nObjective candidate: reg:absoluteerror\n\nStack trace:\n  [bt] (0) /usr/local/lib/python3.10/dist-packages/xgboost/lib/libxgboost.so(+0x1ba24e) [0x7ebdc8b2024e]\n  [bt] (1) /usr/local/lib/python3.10/dist-packages/xgboost/lib/libxgboost.so(+0x60c6ce) [0x7ebdc8f726ce]\n  [bt] (2) /usr/local/lib/python3.10/dist-packages/xgboost/lib/libxgboost.so(+0x4b9c3f) [0x7ebdc8e1fc3f]\n  [bt] (3) /usr/local/lib/python3.10/dist-packages/xgboost/lib/libxgboost.so(+0x4cccd3) [0x7ebdc8e32cd3]\n  [bt] (4) /usr/local/lib/python3.10/dist-packages/xgboost/lib/libxgboost.so(+0x4c5268) [0x7ebdc8e2b268]\n  [bt] (5) /usr/local/lib/python3.10/dist-packages/xgboost/lib/libxgboost.so(XGBoosterUpdateOneIter+0x70) [0x7ebdc8ac7ef0]\n  [bt] (6) /lib/x86_64-linux-gnu/libffi.so.8(+0x7e2e) [0x7ebe31e94e2e]\n  [bt] (7) /lib/x86_64-linux-gnu/libffi.so.8(+0x4493) [0x7ebe31e91493]\n  [bt] (8) /usr/lib/python3.10/lib-dynload/_ctypes.cpython-310-x86_64-linux-gnu.so(+0xa3e9) [0x7ebe31eba3e9]\n\n\n\n--------------------------------------------------------------------------------\n42 fits failed with the following error:\nTraceback (most recent call last):\n  File \"/usr/local/lib/python3.10/dist-packages/sklearn/model_selection/_validation.py\", line 686, in _fit_and_score\n    estimator.fit(X_train, y_train, **fit_params)\n  File \"/usr/local/lib/python3.10/dist-packages/xgboost/core.py\", line 730, in inner_f\n    return func(**kwargs)\n  File \"/usr/local/lib/python3.10/dist-packages/xgboost/sklearn.py\", line 1090, in fit\n    self._Booster = train(\n  File \"/usr/local/lib/python3.10/dist-packages/xgboost/core.py\", line 730, in inner_f\n    return func(**kwargs)\n  File \"/usr/local/lib/python3.10/dist-packages/xgboost/training.py\", line 181, in train\n    bst.update(dtrain, i, obj)\n  File \"/usr/local/lib/python3.10/dist-packages/xgboost/core.py\", line 2050, in update\n    _check_call(\n  File \"/usr/local/lib/python3.10/dist-packages/xgboost/core.py\", line 282, in _check_call\n    raise XGBoostError(py_str(_LIB.XGBGetLastError()))\nxgboost.core.XGBoostError: [19:44:56] /workspace/src/objective/objective.cc:27: Unknown objective function: `squaredeerror`\nObjective candidate: rank:ndcg\nObjective candidate: rank:pairwise\nObjective candidate: rank:map\nObjective candidate: survival:aft\nObjective candidate: binary:hinge\nObjective candidate: multi:softmax\nObjective candidate: multi:softprob\nObjective candidate: reg:quantileerror\nObjective candidate: reg:squarederror\nObjective candidate: reg:squaredlogerror\nObjective candidate: reg:logistic\nObjective candidate: binary:logistic\nObjective candidate: binary:logitraw\nObjective candidate: reg:linear\nObjective candidate: reg:pseudohubererror\nObjective candidate: count:poisson\nObjective candidate: survival:cox\nObjective candidate: reg:gamma\nObjective candidate: reg:tweedie\nObjective candidate: reg:absoluteerror\n\nStack trace:\n  [bt] (0) /usr/local/lib/python3.10/dist-packages/xgboost/lib/libxgboost.so(+0x1ba24e) [0x7ebdc8b2024e]\n  [bt] (1) /usr/local/lib/python3.10/dist-packages/xgboost/lib/libxgboost.so(+0x60c6ce) [0x7ebdc8f726ce]\n  [bt] (2) /usr/local/lib/python3.10/dist-packages/xgboost/lib/libxgboost.so(+0x4b9c3f) [0x7ebdc8e1fc3f]\n  [bt] (3) /usr/local/lib/python3.10/dist-packages/xgboost/lib/libxgboost.so(+0x4cccd3) [0x7ebdc8e32cd3]\n  [bt] (4) /usr/local/lib/python3.10/dist-packages/xgboost/lib/libxgboost.so(+0x4c5268) [0x7ebdc8e2b268]\n  [bt] (5) /usr/local/lib/python3.10/dist-packages/xgboost/lib/libxgboost.so(XGBoosterUpdateOneIter+0x70) [0x7ebdc8ac7ef0]\n  [bt] (6) /lib/x86_64-linux-gnu/libffi.so.8(+0x7e2e) [0x7ebe31e94e2e]\n  [bt] (7) /lib/x86_64-linux-gnu/libffi.so.8(+0x4493) [0x7ebe31e91493]\n  [bt] (8) /usr/lib/python3.10/lib-dynload/_ctypes.cpython-310-x86_64-linux-gnu.so(+0xa3e9) [0x7ebe31eba3e9]\n\n\n\n--------------------------------------------------------------------------------\n41 fits failed with the following error:\nTraceback (most recent call last):\n  File \"/usr/local/lib/python3.10/dist-packages/sklearn/model_selection/_validation.py\", line 686, in _fit_and_score\n    estimator.fit(X_train, y_train, **fit_params)\n  File \"/usr/local/lib/python3.10/dist-packages/xgboost/core.py\", line 730, in inner_f\n    return func(**kwargs)\n  File \"/usr/local/lib/python3.10/dist-packages/xgboost/sklearn.py\", line 1090, in fit\n    self._Booster = train(\n  File \"/usr/local/lib/python3.10/dist-packages/xgboost/core.py\", line 730, in inner_f\n    return func(**kwargs)\n  File \"/usr/local/lib/python3.10/dist-packages/xgboost/training.py\", line 181, in train\n    bst.update(dtrain, i, obj)\n  File \"/usr/local/lib/python3.10/dist-packages/xgboost/core.py\", line 2050, in update\n    _check_call(\n  File \"/usr/local/lib/python3.10/dist-packages/xgboost/core.py\", line 282, in _check_call\n    raise XGBoostError(py_str(_LIB.XGBGetLastError()))\nxgboost.core.XGBoostError: [19:44:57] /workspace/src/objective/objective.cc:27: Unknown objective function: `squaredeerror`\nObjective candidate: rank:ndcg\nObjective candidate: rank:pairwise\nObjective candidate: rank:map\nObjective candidate: survival:aft\nObjective candidate: binary:hinge\nObjective candidate: multi:softmax\nObjective candidate: multi:softprob\nObjective candidate: reg:quantileerror\nObjective candidate: reg:squarederror\nObjective candidate: reg:squaredlogerror\nObjective candidate: reg:logistic\nObjective candidate: binary:logistic\nObjective candidate: binary:logitraw\nObjective candidate: reg:linear\nObjective candidate: reg:pseudohubererror\nObjective candidate: count:poisson\nObjective candidate: survival:cox\nObjective candidate: reg:gamma\nObjective candidate: reg:tweedie\nObjective candidate: reg:absoluteerror\n\nStack trace:\n  [bt] (0) /usr/local/lib/python3.10/dist-packages/xgboost/lib/libxgboost.so(+0x1ba24e) [0x7ebdc8b2024e]\n  [bt] (1) /usr/local/lib/python3.10/dist-packages/xgboost/lib/libxgboost.so(+0x60c6ce) [0x7ebdc8f726ce]\n  [bt] (2) /usr/local/lib/python3.10/dist-packages/xgboost/lib/libxgboost.so(+0x4b9c3f) [0x7ebdc8e1fc3f]\n  [bt] (3) /usr/local/lib/python3.10/dist-packages/xgboost/lib/libxgboost.so(+0x4cccd3) [0x7ebdc8e32cd3]\n  [bt] (4) /usr/local/lib/python3.10/dist-packages/xgboost/lib/libxgboost.so(+0x4c5268) [0x7ebdc8e2b268]\n  [bt] (5) /usr/local/lib/python3.10/dist-packages/xgboost/lib/libxgboost.so(XGBoosterUpdateOneIter+0x70) [0x7ebdc8ac7ef0]\n  [bt] (6) /lib/x86_64-linux-gnu/libffi.so.8(+0x7e2e) [0x7ebe31e94e2e]\n  [bt] (7) /lib/x86_64-linux-gnu/libffi.so.8(+0x4493) [0x7ebe31e91493]\n  [bt] (8) /usr/lib/python3.10/lib-dynload/_ctypes.cpython-310-x86_64-linux-gnu.so(+0xa3e9) [0x7ebe31eba3e9]\n\n\n\n--------------------------------------------------------------------------------\n41 fits failed with the following error:\nTraceback (most recent call last):\n  File \"/usr/local/lib/python3.10/dist-packages/sklearn/model_selection/_validation.py\", line 686, in _fit_and_score\n    estimator.fit(X_train, y_train, **fit_params)\n  File \"/usr/local/lib/python3.10/dist-packages/xgboost/core.py\", line 730, in inner_f\n    return func(**kwargs)\n  File \"/usr/local/lib/python3.10/dist-packages/xgboost/sklearn.py\", line 1090, in fit\n    self._Booster = train(\n  File \"/usr/local/lib/python3.10/dist-packages/xgboost/core.py\", line 730, in inner_f\n    return func(**kwargs)\n  File \"/usr/local/lib/python3.10/dist-packages/xgboost/training.py\", line 181, in train\n    bst.update(dtrain, i, obj)\n  File \"/usr/local/lib/python3.10/dist-packages/xgboost/core.py\", line 2050, in update\n    _check_call(\n  File \"/usr/local/lib/python3.10/dist-packages/xgboost/core.py\", line 282, in _check_call\n    raise XGBoostError(py_str(_LIB.XGBGetLastError()))\nxgboost.core.XGBoostError: [19:44:58] /workspace/src/objective/objective.cc:27: Unknown objective function: `squaredeerror`\nObjective candidate: rank:ndcg\nObjective candidate: rank:pairwise\nObjective candidate: rank:map\nObjective candidate: survival:aft\nObjective candidate: binary:hinge\nObjective candidate: multi:softmax\nObjective candidate: multi:softprob\nObjective candidate: reg:quantileerror\nObjective candidate: reg:squarederror\nObjective candidate: reg:squaredlogerror\nObjective candidate: reg:logistic\nObjective candidate: binary:logistic\nObjective candidate: binary:logitraw\nObjective candidate: reg:linear\nObjective candidate: reg:pseudohubererror\nObjective candidate: count:poisson\nObjective candidate: survival:cox\nObjective candidate: reg:gamma\nObjective candidate: reg:tweedie\nObjective candidate: reg:absoluteerror\n\nStack trace:\n  [bt] (0) /usr/local/lib/python3.10/dist-packages/xgboost/lib/libxgboost.so(+0x1ba24e) [0x7ebdc8b2024e]\n  [bt] (1) /usr/local/lib/python3.10/dist-packages/xgboost/lib/libxgboost.so(+0x60c6ce) [0x7ebdc8f726ce]\n  [bt] (2) /usr/local/lib/python3.10/dist-packages/xgboost/lib/libxgboost.so(+0x4b9c3f) [0x7ebdc8e1fc3f]\n  [bt] (3) /usr/local/lib/python3.10/dist-packages/xgboost/lib/libxgboost.so(+0x4cccd3) [0x7ebdc8e32cd3]\n  [bt] (4) /usr/local/lib/python3.10/dist-packages/xgboost/lib/libxgboost.so(+0x4c5268) [0x7ebdc8e2b268]\n  [bt] (5) /usr/local/lib/python3.10/dist-packages/xgboost/lib/libxgboost.so(XGBoosterUpdateOneIter+0x70) [0x7ebdc8ac7ef0]\n  [bt] (6) /lib/x86_64-linux-gnu/libffi.so.8(+0x7e2e) [0x7ebe31e94e2e]\n  [bt] (7) /lib/x86_64-linux-gnu/libffi.so.8(+0x4493) [0x7ebe31e91493]\n  [bt] (8) /usr/lib/python3.10/lib-dynload/_ctypes.cpython-310-x86_64-linux-gnu.so(+0xa3e9) [0x7ebe31eba3e9]\n\n\n\n--------------------------------------------------------------------------------\n27 fits failed with the following error:\nTraceback (most recent call last):\n  File \"/usr/local/lib/python3.10/dist-packages/sklearn/model_selection/_validation.py\", line 686, in _fit_and_score\n    estimator.fit(X_train, y_train, **fit_params)\n  File \"/usr/local/lib/python3.10/dist-packages/xgboost/core.py\", line 730, in inner_f\n    return func(**kwargs)\n  File \"/usr/local/lib/python3.10/dist-packages/xgboost/sklearn.py\", line 1090, in fit\n    self._Booster = train(\n  File \"/usr/local/lib/python3.10/dist-packages/xgboost/core.py\", line 730, in inner_f\n    return func(**kwargs)\n  File \"/usr/local/lib/python3.10/dist-packages/xgboost/training.py\", line 181, in train\n    bst.update(dtrain, i, obj)\n  File \"/usr/local/lib/python3.10/dist-packages/xgboost/core.py\", line 2050, in update\n    _check_call(\n  File \"/usr/local/lib/python3.10/dist-packages/xgboost/core.py\", line 282, in _check_call\n    raise XGBoostError(py_str(_LIB.XGBGetLastError()))\nxgboost.core.XGBoostError: [19:44:59] /workspace/src/objective/objective.cc:27: Unknown objective function: `squaredeerror`\nObjective candidate: rank:ndcg\nObjective candidate: rank:pairwise\nObjective candidate: rank:map\nObjective candidate: survival:aft\nObjective candidate: binary:hinge\nObjective candidate: multi:softmax\nObjective candidate: multi:softprob\nObjective candidate: reg:quantileerror\nObjective candidate: reg:squarederror\nObjective candidate: reg:squaredlogerror\nObjective candidate: reg:logistic\nObjective candidate: binary:logistic\nObjective candidate: binary:logitraw\nObjective candidate: reg:linear\nObjective candidate: reg:pseudohubererror\nObjective candidate: count:poisson\nObjective candidate: survival:cox\nObjective candidate: reg:gamma\nObjective candidate: reg:tweedie\nObjective candidate: reg:absoluteerror\n\nStack trace:\n  [bt] (0) /usr/local/lib/python3.10/dist-packages/xgboost/lib/libxgboost.so(+0x1ba24e) [0x7ebdc8b2024e]\n  [bt] (1) /usr/local/lib/python3.10/dist-packages/xgboost/lib/libxgboost.so(+0x60c6ce) [0x7ebdc8f726ce]\n  [bt] (2) /usr/local/lib/python3.10/dist-packages/xgboost/lib/libxgboost.so(+0x4b9c3f) [0x7ebdc8e1fc3f]\n  [bt] (3) /usr/local/lib/python3.10/dist-packages/xgboost/lib/libxgboost.so(+0x4cccd3) [0x7ebdc8e32cd3]\n  [bt] (4) /usr/local/lib/python3.10/dist-packages/xgboost/lib/libxgboost.so(+0x4c5268) [0x7ebdc8e2b268]\n  [bt] (5) /usr/local/lib/python3.10/dist-packages/xgboost/lib/libxgboost.so(XGBoosterUpdateOneIter+0x70) [0x7ebdc8ac7ef0]\n  [bt] (6) /lib/x86_64-linux-gnu/libffi.so.8(+0x7e2e) [0x7ebe31e94e2e]\n  [bt] (7) /lib/x86_64-linux-gnu/libffi.so.8(+0x4493) [0x7ebe31e91493]\n  [bt] (8) /usr/lib/python3.10/lib-dynload/_ctypes.cpython-310-x86_64-linux-gnu.so(+0xa3e9) [0x7ebe31eba3e9]\n\n\n"
          ]
        }
      ]
    },
    {
      "cell_type": "code",
      "source": [],
      "metadata": {
        "id": "FZN8K-YlLuOY"
      },
      "execution_count": null,
      "outputs": []
    },
    {
      "cell_type": "code",
      "source": [
        "xgbGridModel.best_params_"
      ],
      "metadata": {
        "colab": {
          "base_uri": "https://localhost:8080/",
          "height": 141
        },
        "id": "9oSeGIjQLGBy",
        "outputId": "ed20d7f7-f5fa-4721-8658-91adf495370b"
      },
      "execution_count": 44,
      "outputs": [
        {
          "output_type": "error",
          "ename": "NameError",
          "evalue": "name 'xgbGridModel' is not defined",
          "traceback": [
            "\u001b[0;31m---------------------------------------------------------------------------\u001b[0m",
            "\u001b[0;31mNameError\u001b[0m                                 Traceback (most recent call last)",
            "\u001b[0;32m<ipython-input-44-b7acd5257a71>\u001b[0m in \u001b[0;36m<cell line: 1>\u001b[0;34m()\u001b[0m\n\u001b[0;32m----> 1\u001b[0;31m \u001b[0mxgbGridModel\u001b[0m\u001b[0;34m.\u001b[0m\u001b[0mbest_params_\u001b[0m\u001b[0;34m\u001b[0m\u001b[0;34m\u001b[0m\u001b[0m\n\u001b[0m",
            "\u001b[0;31mNameError\u001b[0m: name 'xgbGridModel' is not defined"
          ]
        }
      ]
    },
    {
      "cell_type": "code",
      "source": [
        "yGrid = xgbGridModel.predict(X_test)"
      ],
      "metadata": {
        "id": "1FtgYOAyLu6i"
      },
      "execution_count": null,
      "outputs": []
    },
    {
      "cell_type": "code",
      "source": [
        "MSEGrid = mean_squared_error(y_test, yGrid)\n",
        "RMSEGrid = mean_squared_error(y_test, yGrid)"
      ],
      "metadata": {
        "id": "kR-MxC2OLyTz"
      },
      "execution_count": null,
      "outputs": []
    }
  ]
}